Workbook

Sheet Plan - NL
B1: Runde | C1: Dag | D1: Dato | E1: Måned | F1: Tidspunkt | G1: Hjemme | H1: Ude | I1: R | J1: U | K1: D | L1: L | M1: B | N1: F | O1: S | P1: C | Q1: Note | R1: Antal tilmeldte 20-Mar 11:30 | S1: 1s | T1: 2s | U1: 3s | V1: Taske | W1: Taske IND | X1: Taske UD | Y1: Betaling | Z1: Video | AA1: Gennemseer | AB1: GameID | AC1: Game start | AD1: Game end | AE1: Video Exchanged. | AF1: Game time (easy) | AG1: Intercut time (min) | AH1: Exchange of Breakdown data | AI1: Return of break down data | AK1: Upload time | AL1: Breakdown time | AM1: Game time
A2: Vedligeholdende | B2: 0 | C2: Søndag | D2: 29 | E2: Marts | F2: 0.41666667 | G2: Towers | H2: Demons | I2: FK | J2: DS | K2: VN | L2: MM | Q2: Klubcrew: Spartans | R2: 2 | AB2: =D2&E2&"-"&G2&"-v-"&H2 -> 29Marts-Towers-v-Demons
A3: Vedligeholdende | B3: 0 | C3: Mandag | D3: 6 | E3: April | F3: 0.66666667 | G3: Tigers | H3: Razorbacks | I3: KL | J3: JL | K3: TO | Q3: Klubcrew: Badgers | R3: 0 | AB3: =D3&E3&"-"&G3&"-v-"&H3 -> 6April-Tigers-v-Razorbacks
A4: NL | B4: 2 | C4: Lørdag | D4: 11 | E4: April | F4: 0.58333333 | G4: Towers | H4: Razorbacks | I4: FR | J4: DS | K4: HP | L4: TH | M4: AT | N4: ER | O4: TK | AB4: =D4&E4&"-"&G4&"-v-"&H4 -> 11April-Towers-v-Razorbacks
A5: NL | B5: 2 | C5: Søndag | D5: 12 | E5: April | F5: 0.58333333 | G5: 89ers | H5: Tigers | I5: MR | J5: AR | K5: JL | L5: NI | M5: BT | N5: KL | O5: TM | AB5: =D5&E5&"-"&G5&"-v-"&H5 -> 12April-89ers-v-Tigers
A6: NL | B6: 2 | C6: Søndag | D6: 12 | E6: April | F6: 0.58333333 | G6: Oaks | H6: Gold Diggers | I6: DS | J6: LT | K6: MM | L6: RH | N6: KJ | O6: FR | AB6: =D6&E6&"-"&G6&"-v-"&H6 -> 12April-Oaks-v-Gold Diggers
A7: NL | B7: 4 | C7: Lørdag | D7: 25 | E7: April | F7: 0.58333333 | G7: 89ers | H7: Gold Diggers | I7: MR | J7: AR | K7: NI | L7: JL | N7: KL | O7: TM | AB7: =D7&E7&"-"&G7&"-v-"&H7 -> 25April-89ers-v-Gold Diggers
A8: NL | B8: 4 | C8: Lørdag | D8: 25 | E8: April | F8: 0.58333333 | G8: Towers | H8: Tigers | I8: DS | J8: LT | K8: HP | L8: JE | N8: KJ | O8: ER | S8: =COUNTIF('Status data'!$A5:$H5,"1") -> 0 | T8: =COUNTIF('Status data'!$A5:$H5,"2") -> 0 | U8: =COUNTIF('Status data'!$A5:$H5,"3") -> 0 | AB8: =D8&E8&"-"&G8&"-v-"&H8 -> 25April-Towers-v-Tigers
A9: NL | B9: 4 | C9: Søndag | D9: 26 | E9: April | F9: 0.58333333 | G9: Razorbacks | H9: Oaks | I9: MR | J9: DS | K9: TO | L9: ER | M9: BT | N9: KL | O9: TM | S9: =COUNTIF('Status data'!$A6:$H6,"1") -> 2 | T9: =COUNTIF('Status data'!$A6:$H6,"2") -> 1 | U9: =COUNTIF('Status data'!$A6:$H6,"3") -> 1 | AB9: =D9&E9&"-"&G9&"-v-"&H9 -> 26April-Razorbacks-v-Oaks
A10: NL | B10: 6 | C10: Lørdag | D10: 9 | E10: Maj | F10: 0.58333333 | G10: Gold Diggers | H10: Towers | I10: FR | J10: DS | K10: TO | L10: VN | M10: BT | N10: ER | O10: KL | S10: =COUNTIF('Status data'!$A7:$H7,"1") -> 0 | T10: =COUNTIF('Status data'!$A7:$H7,"2") -> 0 | U10: =COUNTIF('Status data'!$A7:$H7,"3") -> 0 | AB10: =D10&E10&"-"&G10&"-v-"&H10 -> 9Maj-Gold Diggers-v-Towers
A11: NL | B11: 6 | C11: Lørdag | D11: 9 | E11: Maj | F11: 0.58333333 | G11: Oaks | H11: 89ers | I11: FK | J11: LT | K11: MM | L11: TH | M11: JE | N11: KJ | O11: AT | S11: =COUNTIF('Status data'!$A8:$H8,"1") -> 0 | T11: =COUNTIF('Status data'!$A8:$H8,"2") -> 0 | U11: =COUNTIF('Status data'!$A8:$H8,"3") -> 0 | AB11: =D11&E11&"-"&G11&"-v-"&H11 -> 9Maj-Oaks-v-89ers
A12: NL | B12: 6 | C12: Søndag | D12: 10 | E12: Maj | F12: 0.58333333 | G12: Tigers | H12: Razorbacks | I12: MR | J12: AR | K12: JL | L12: NI | M12: BT | N12: KL | O12: TM | S12: =COUNTIF('Status data'!$A9:$H9,"1") -> 0 | T12: =COUNTIF('Status data'!$A9:$H9,"2") -> 0 | U12: =COUNTIF('Status data'!$A9:$H9,"3") -> 0 | AB12: =D12&E12&"-"&G12&"-v-"&H12 -> 10Maj-Tigers-v-Razorbacks | AF12: =HOUR(AD12-AC12)&"h"&minute(AD12-AC12)&"m" -> 0h0m | AK12: =AE12-AD12 -> 0
A13: NL | B13: 9 | C13: Fredag | D13: 29 | E13: Maj | F13: 0.75 | G13: Towers | H13: Oaks | I13: FR | J13: DS | K13: MM | L13: VN | M13: AT | N13: KJ | O13: ER | S13: =COUNTIF('Status data'!$A10:$H10,"1") -> 0 | T13: =COUNTIF('Status data'!$A10:$H10,"2") -> 0 | U13: =COUNTIF('Status data'!$A10:$H10,"3") -> 0 | AB13: =D13&E13&"-"&G13&"-v-"&H13 -> 29Maj-Towers-v-Oaks
A14: NL | B14: 9 | C14: Lørdag | D14: 30 | E14: Maj | F14: 0.58333333 | G14: Tigers | H14: Gold Diggers | I14: MR | J14: AR | K14: TS | L14: JL | N14: KL | O14: BT | S14: =COUNTIF('Status data'!$A11:$H11,"1") -> 0 | T14: =COUNTIF('Status data'!$A11:$H11,"2") -> 0 | U14: =COUNTIF('Status data'!$A11:$H11,"3") -> 0 | AB14: =D14&E14&"-"&G14&"-v-"&H14 -> 30Maj-Tigers-v-Gold Diggers
A15: NL | B15: 9 | C15: Søndag | D15: 31 | E15: Maj | F15: 0.58333333 | G15: Razorbacks | H15: 89ers | I15: FR | J15: DS | K15: TS | L15: KE | M15: JE | N15: KL | O15: TK | S15: =COUNTIF('Status data'!$A12:$H12,"1") -> 4 | T15: =COUNTIF('Status data'!$A12:$H12,"2") -> 0 | U15: =COUNTIF('Status data'!$A12:$H12,"3") -> 1 | AB15: =D15&E15&"-"&G15&"-v-"&H15 -> 31Maj-Razorbacks-v-89ers
A16: NL | B16: 11 | C16: Lørdag | D16: 13 | E16: Juni | F16: 0.58333333 | G16: 89ers | H16: Towers | I16: AR | J16: TS | K16: JL | L16: NI | N16: KL | O16: BT | T16: =COUNTIF('Status data'!$A13:$H13,"1") -> 0 | U16: =COUNTIF('Status data'!$A13:$H13,"2") -> 0 | AB16: =D16&E16&"-"&G16&"-v-"&H16 -> 13Juni-89ers-v-Towers
A17: NL | B17: 11 | C17: Lørdag | D17: 13 | E17: Juni | F17: 0.58333333 | G17: Oaks | H17: Tigers | I17: DS | J17: KE | K17: MM | L17: Lasse Schrøder | M17: JE | N17: ER | O17: TK | AB17: =D17&E17&"-"&G17&"-v-"&H17 -> 13Juni-Oaks-v-Tigers
A18: NL | B18: 12 | C18: Lørdag | D18: 20 | E18: Juni | F18: 0.58333333 | G18: Gold Diggers | H18: Oaks | I18: DS | J18: LT | K18: MM | L18: Lasse Schrøder | M18: (SE) | N18: KJ | O18: (SE) | S18: =COUNTIF('Status data'!$A14:$H14,"1") -> 0 | T18: =COUNTIF('Status data'!$A14:$H14,"2") -> 0 | U18: =COUNTIF('Status data'!$A14:$H14,"3") -> 0 | AB18: =D18&E18&"-"&G18&"-v-"&H18 -> 20Juni-Gold Diggers-v-Oaks
A19: NL | B19: 12 | C19: Lørdag | D19: 20 | E19: Juni | F19: 0.58333333 | G19: Razorbacks | H19: Towers | I19: MR | J19: AR | K19: TO | L19: JL | M19: BT | N19: ER | O19: TM | AB19: =D19&E19&"-"&G19&"-v-"&H19 -> 20Juni-Razorbacks-v-Towers
A20: NL | B20: 12 | C20: Søndag | D20: 21 | E20: Juni | F20: 0.58333333 | G20: Tigers | H20: 89ers | I20: FR | J20: DS | K20: NI | L20: MP | M20: MR | N20: KL | O20: TM | S20: =COUNTIF('Status data'!$A17:$H17,"1") -> 0 | T20: =COUNTIF('Status data'!$A17:$H17,"2") -> 0 | U20: =COUNTIF('Status data'!$A17:$H17,"3") -> 0 | AB20: =D20&E20&"-"&G20&"-v-"&H20 -> 21Juni-Tigers-v-89ers
A21: NL | B21: 16 | C21: Lørdag | D21: 15 | E21: August | F21: 0.58333333 | G21: Gold Diggers | H21: Razorbacks | I21: DS | J21: LT | K21: MM | L21: TH | M21: JE | N21: KJ | O21: ER | Q21: Flyttet fra 14/6. | AB21: =D21&E21&"-"&G21&"-v-"&H21 -> 15August-Gold Diggers-v-Razorbacks
A22: NL | B22: 17 | C22: Fredag | D22: 21 | E22: August | F22: 0.75 | G22: Towers | H22: Gold Diggers | I22: FR | J22: DS | K22: HP | L22: KE | M22: AT | N22: ER | O22: KJ | AB22: =D22&E22&"-"&G22&"-v-"&H22 -> 21August-Towers-v-Gold Diggers
A23: NL | B23: 17 | C23: Lørdag | D23: 22 | E23: August | F23: 0.58333333 | G23: 89ers | H23: Oaks | I23: MR | J23: AR | K23: NI | L23: AL | M23: BT | N23: KL | O23: TO | S23: =COUNTIF('Status data'!$A18:$H18,"1") -> 0 | T23: =COUNTIF('Status data'!$A18:$H18,"2") -> 0 | U23: =COUNTIF('Status data'!$A18:$H18,"3") -> 0 | AB23: =D23&E23&"-"&G23&"-v-"&H23 -> 22August-89ers-v-Oaks
A24: NL | B24: 17 | C24: Søndag | D24: 23 | E24: August | F24: 0.58333333 | G24: Razorbacks | H24: Tigers | I24: FR | J24: LT | K24: TO | L24: JL | M24: TS | N24: KL | O24: AL | AB24: =D24&E24&"-"&G24&"-v-"&H24 -> 23August-Razorbacks-v-Tigers
A25: NL | B25: 19 | C25: Lørdag | D25: 5 | E25: September | F25: 0.58333333 | G25: Gold Diggers | H25: 89ers | I25: FR | J25: DS | K25: HP | L25: KE | M25: JE | N25: ER | O25: KJ | S25: =COUNTIF('Status data'!$A20:$H20,"1") -> 0 | T25: =COUNTIF('Status data'!$A20:$H20,"2") -> 0 | U25: =COUNTIF('Status data'!$A20:$H20,"3") -> 0 | AB25: =D25&E25&"-"&G25&"-v-"&H25 -> 5September-Gold Diggers-v-89ers
A26: NL | B26: 19 | C26: Lørdag | D26: 5 | E26: September | F26: 0.58333333 | G26: Tigers | H26: Towers | I26: MR | J26: AR | K26: TS | L26: JL | M26: BT | N26: KL | O26: TM | S26: =COUNTIF('Status data'!$A23:$H23,"1") -> 0 | T26: =COUNTIF('Status data'!$A23:$H23,"2") -> 0 | U26: =COUNTIF('Status data'!$A23:$H23,"3") -> 0 | AB26: =D26&E26&"-"&G26&"-v-"&H26 -> 5September-Tigers-v-Towers
A27: NL | B27: 19 | C27: Søndag | D27: 6 | E27: September | F27: 0.58333333 | G27: Oaks | H27: Razorbacks | I27: FR | J27: LT | K27: MM | L27: TH | M27: AT | N27: KJ | O27: TK | AB27: =D27&E27&"-"&G27&"-v-"&H27 -> 6September-Oaks-v-Razorbacks
A28: NL | B28: 22 | C28: Lørdag | D28: 19 | E28: September | F28: 0.58333333 | G28: Razorbacks | H28: Gold Diggers | AB28: =D28&E28&"-"&G28&"-v-"&H28 -> 19September-Razorbacks-v-Gold Diggers
A29: NL | B29: 22 | C29: Lørdag | D29: 19 | E29: September | F29: 0.58333333 | G29: 89ers | H29: Towers | AB29: =D29&E29&"-"&G29&"-v-"&H29 -> 19September-89ers-v-Towers
A30: U16 | B30: 23 | C30: Lørdag | D30: 3 | E30: Oktober | F30: 0.54166667 | G30: U16 Challenge Bowl
A31: NL | B31: 23 | C31: Lørdag | D31: 3 | E31: Oktober | F31: 0.70833333 | G31: Mermaid Bowl | AB31: =D31&E31&"-"&G31&"-v-"&H31 -> 3Oktober-Mermaid Bowl-v-
A35: Navn | B35: Initialer | C35: Kurser | D35: NL forår | E35: Vest forår | F35: Øst forår | G35: Assignment Forår | H35: NL efterår (grundspil) | I35: NL totalt (grundspil) | J35: In-stribes Total (grundspil)
A36: Michael Rahbek | B36: MR | C36: {=IF($A36="","",SUM(($A$2:$A$31="Vedligeholdende")*($I$2:$P$31=$B36)))} -> 0 | D36: {=IF($A36="","",SUM(($A$2:$A$20="NL")*($I$2:$P$20=$B36)))} -> 7 | E36: {=IF($A36="","",SUM(($G$4:$G$20="Razorbacks")*($I$4:$P$20=$B36))+SUM(($G$4:$G$20="Tigers")*($I$4:$P$20=$B36))+SUM(($G$4:$G$20="89ers")*($I$4:$P$20=$B36)))} -> 7 | F36: {=IF($A36="","",SUM(($G$4:$G$20="Oaks")*($I$4:$P$20=$B36))+SUM(($G$4:$G$20="Gold Diggers")*($I$4:$P$20=$B36))+SUM(($G$4:$G$20="Towers")*($I$4:$P$20=$B36)))} -> 0 | G36: =IF($A36="","",C36+D36) -> 7 | H36: {=IF($A36="","",SUM(($A$21:$A$27="NL")*($I$21:$P$27=$B36)))} -> 2 | I36: {=IF($A36="","",SUM(($A$2:$A$27="NL")*($I$2:$P$27=$B36)))} -> 9 | J36: =IF($A36="","",COUNTIF($I$2:$P$27,$B36)-C36) -> 9
A37: Frank Rasmussen | B37: FR | C37: {=IF($A37="","",SUM(($A$2:$A$31="Vedligeholdende")*($I$2:$P$31=$B37)))} -> 0 | D37: {=IF($A37="","",SUM(($A$2:$A$20="NL")*($I$2:$P$20=$B37)))} -> 6 | E37: {=IF($A37="","",SUM(($G$4:$G$20="Razorbacks")*($I$4:$P$20=$B37))+SUM(($G$4:$G$20="Tigers")*($I$4:$P$20=$B37))+SUM(($G$4:$G$20="89ers")*($I$4:$P$20=$B37)))} -> 2 | F37: {=IF($A37="","",SUM(($G$4:$G$20="Oaks")*($I$4:$P$20=$B37))+SUM(($G$4:$G$20="Gold Diggers")*($I$4:$P$20=$B37))+SUM(($G$4:$G$20="Towers")*($I$4:$P$20=$B37)))} -> 4 | G37: =IF($A37="","",C37+D37) -> 6 | H37: {=IF($A37="","",SUM(($A$21:$A$27="NL")*($I$21:$P$27=$B37)))} -> 4 | I37: {=IF($A37="","",SUM(($A$2:$A$27="NL")*($I$2:$P$27=$B37)))} -> 10 | J37: =IF($A37="","",COUNTIF($I$2:$P$27,$B37)-C37) -> 10 | Q37: =DATA!I65 | V37: =SUM(Y1:Y25) -> 0 | W37: 2 | X37: medium
A38: Frank Kristensen | B38: FK | C38: {=IF($A38="","",SUM(($A$2:$A$31="Vedligeholdende")*($I$2:$P$31=$B38)))} -> 1 | D38: {=IF($A38="","",SUM(($A$2:$A$20="NL")*($I$2:$P$20=$B38)))} -> 1 | E38: {=IF($A38="","",SUM(($G$4:$G$20="Razorbacks")*($I$4:$P$20=$B38))+SUM(($G$4:$G$20="Tigers")*($I$4:$P$20=$B38))+SUM(($G$4:$G$20="89ers")*($I$4:$P$20=$B38)))} -> 0 | F38: {=IF($A38="","",SUM(($G$4:$G$20="Oaks")*($I$4:$P$20=$B38))+SUM(($G$4:$G$20="Gold Diggers")*($I$4:$P$20=$B38))+SUM(($G$4:$G$20="Towers")*($I$4:$P$20=$B38)))} -> 1 | G38: =IF($A38="","",C38+D38) -> 2 | H38: {=IF($A38="","",SUM(($A$21:$A$27="NL")*($I$21:$P$27=$B38)))} -> 0 | I38: {=IF($A38="","",SUM(($A$2:$A$27="NL")*($I$2:$P$27=$B38)))} -> 1 | J38: =IF($A38="","",COUNTIF($I$2:$P$27,$B38)-C38) -> 1
C39: {=IF($A39="","",SUM(($A$2:$A$31="Vedligeholdende")*($I$2:$P$31=$B39)))} | D39: {=IF($A39="","",SUM(($A$2:$A$17="NL")*($I$2:$P$17=$B39)))} | E39: {=IF($A39="","",SUM(($G$4:$G$17="Razorbacks")*($I$4:$P$17=$B39))+SUM(($G$4:$G$17="Tigers")*($I$4:$P$17=$B39))+SUM(($G$4:$G$17="89ers")*($I$4:$P$17=$B39)))} | F39: {=IF($A39="","",SUM(($G$4:$G$17="Oaks")*($I$4:$P$17=$B39))+SUM(($G$4:$G$17="Gold Diggers")*($I$4:$P$17=$B39))+SUM(($G$4:$G$17="Towers")*($I$4:$P$17=$B39)))} | G39: =IF($A39="","",C39+D39) | H39: {=IF($A39="","",SUM(($A$18:$A$26="NL")*($I$18:$P$26=$B39)))} | I39: {=IF($A39="","",SUM(($A$2:$A$26="NL")*($I$2:$P$26=$B39)))} | J39: =IF($A39="","",COUNTIF($I$2:$P$26,$B39)-C39)
A40: Asbjørn Rohold | B40: AR | C40: {=IF($A40="","",SUM(($A$2:$A$31="Vedligeholdende")*($I$2:$P$31=$B40)))} -> 0 | D40: {=IF($A40="","",SUM(($A$2:$A$20="NL")*($I$2:$P$20=$B40)))} -> 6 | E40: {=IF($A40="","",SUM(($G$4:$G$20="Razorbacks")*($I$4:$P$20=$B40))+SUM(($G$4:$G$20="Tigers")*($I$4:$P$20=$B40))+SUM(($G$4:$G$20="89ers")*($I$4:$P$20=$B40)))} -> 6 | F40: {=IF($A40="","",SUM(($G$4:$G$20="Oaks")*($I$4:$P$20=$B40))+SUM(($G$4:$G$20="Gold Diggers")*($I$4:$P$20=$B40))+SUM(($G$4:$G$20="Towers")*($I$4:$P$20=$B40)))} -> 0 | G40: =IF($A40="","",C40+D40) -> 6 | H40: {=IF($A40="","",SUM(($A$21:$A$27="NL")*($I$21:$P$27=$B40)))} -> 2 | I40: {=IF($A40="","",SUM(($A$2:$A$27="NL")*($I$2:$P$27=$B40)))} -> 8 | J40: =IF($A40="","",COUNTIF($I$2:$P$27,$B40)-C40) -> 8 | U40: MEDIAN | V40: =MEDIAN(Y9:Y26) -> #NUM! | W40: s | X40: stats
A41: Vincent Nordkov | B41: VN | C41: {=IF($A41="","",SUM(($A$2:$A$31="Vedligeholdende")*($I$2:$P$31=$B41)))} -> 1 | D41: {=IF($A41="","",SUM(($A$2:$A$20="NL")*($I$2:$P$20=$B41)))} -> 2 | E41: {=IF($A41="","",SUM(($G$4:$G$20="Razorbacks")*($I$4:$P$20=$B41))+SUM(($G$4:$G$20="Tigers")*($I$4:$P$20=$B41))+SUM(($G$4:$G$20="89ers")*($I$4:$P$20=$B41)))} -> 0 | F41: {=IF($A41="","",SUM(($G$4:$G$20="Oaks")*($I$4:$P$20=$B41))+SUM(($G$4:$G$20="Gold Diggers")*($I$4:$P$20=$B41))+SUM(($G$4:$G$20="Towers")*($I$4:$P$20=$B41)))} -> 2 | G41: =IF($A41="","",C41+D41) -> 3 | H41: {=IF($A41="","",SUM(($A$21:$A$27="NL")*($I$21:$P$27=$B41)))} -> 0 | I41: {=IF($A41="","",SUM(($A$2:$A$27="NL")*($I$2:$P$27=$B41)))} -> 2 | J41: =IF($A41="","",COUNTIF($I$2:$P$27,$B41)-C41) -> 2
A42: Dennis Svensson | B42: DS | C42: {=IF($A42="","",SUM(($A$2:$A$31="Vedligeholdende")*($I$2:$P$31=$B42)))} -> 1 | D42: {=IF($A42="","",SUM(($A$2:$A$20="NL")*($I$2:$P$20=$B42)))} -> 10 | E42: {=IF($A42="","",SUM(($G$4:$G$20="Razorbacks")*($I$4:$P$20=$B42))+SUM(($G$4:$G$20="Tigers")*($I$4:$P$20=$B42))+SUM(($G$4:$G$20="89ers")*($I$4:$P$20=$B42)))} -> 3 | F42: {=IF($A42="","",SUM(($G$4:$G$20="Oaks")*($I$4:$P$20=$B42))+SUM(($G$4:$G$20="Gold Diggers")*($I$4:$P$20=$B42))+SUM(($G$4:$G$20="Towers")*($I$4:$P$20=$B42)))} -> 7 | G42: =IF($A42="","",C42+D42) -> 11 | H42: {=IF($A42="","",SUM(($A$21:$A$27="NL")*($I$21:$P$27=$B42)))} -> 3 | I42: {=IF($A42="","",SUM(($A$2:$A$27="NL")*($I$2:$P$27=$B42)))} -> 13 | J42: =IF($A42="","",COUNTIF($I$2:$P$27,$B42)-C42) -> 13 | U42: PROJECTED 2 | V42: =SUM(Y9:Y26)/23*40 -> 0 | W42: t | X42: tv
A43: Benjamin Behnke | B43: BB | C43: {=IF($A43="","",SUM(($A$2:$A$31="Vedligeholdende")*($I$2:$P$31=$B43)))} -> 0 | D43: {=IF($A43="","",SUM(($A$2:$A$20="NL")*($I$2:$P$20=$B43)))} -> 0 | E43: {=IF($A43="","",SUM(($G$4:$G$20="Razorbacks")*($I$4:$P$20=$B43))+SUM(($G$4:$G$20="Tigers")*($I$4:$P$20=$B43))+SUM(($G$4:$G$20="89ers")*($I$4:$P$20=$B43)))} -> 0 | F43: {=IF($A43="","",SUM(($G$4:$G$20="Oaks")*($I$4:$P$20=$B43))+SUM(($G$4:$G$20="Gold Diggers")*($I$4:$P$20=$B43))+SUM(($G$4:$G$20="Towers")*($I$4:$P$20=$B43)))} -> 0 | G43: =IF($A43="","",C43+D43) -> 0 | H43: {=IF($A43="","",SUM(($A$21:$A$27="NL")*($I$21:$P$27=$B43)))} -> 0 | I43: {=IF($A43="","",SUM(($A$2:$A$27="NL")*($I$2:$P$27=$B43)))} -> 0 | J43: =IF($A43="","",COUNTIF($I$2:$P$27,$B43)-C43) -> 0
...

Sheet Officials and games
N1: Games
A2: Initialer | B2: Navn | C2: Status | D2: EDK | E2: Primær | F2: Sekundær | G2: Licens | H2: Licens # | I2: Landsdel | J2: Klub | K2: Test | L2: Telefon | M2: Mail | N2: Total | O2: Primary position | P2: In primary group (not primary position) | Q2: Outside primary group
A3: AT | B3: Anders Tronier Hansen | C3: NL | E3: B | G3: NL | I3: Øst | J3: Uafhængig | M3: atronierh@gmail.com | N3: =CountIF('Plan - NL'!$I$8:$P$31,$A3) -> 4 | O3: =COUNTIFS('Plan - NL'!$M$8:$M$31,$A3) -> 3 | P3: =COUNTIFS('Plan - NL'!$N$8:$O$31,$A3) -> 1 | Q3: =COUNTIFS('Plan - NL'!$I$8:$L$31,$A3)+COUNTIFS('Plan - NL'!$P$8:$P$31,$A3) -> 0
A4: JE | B4: Jeppe Sejerø Ternander | C4: NL | D4: Ja | E4: B | F4: Anything | G4: I | H4: 6406 | I4: Øst | J4: Uafhængig | L4: 28711070 | M4: jeppe_s_holm@hotmail.com | N4: =CountIF('Plan - NL'!$I$8:$P$31,$A4) -> 6 | O4: =COUNTIFS('Plan - NL'!$N$8:$N$31,$A4) -> 0 | P4: =COUNTIFS('Plan - NL'!$M$8:$M$31,$A4) + COUNTIFS('Plan - NL'!$O$8:$O$31,$A4) -> 5 | Q4: =COUNTIFS('Plan - NL'!$I$8:$L$31,$A4)+COUNTIFS('Plan - NL'!$P$8:$P$31,$A4) -> 1
A5: BA | B5: Brian Andersen | C5: Pause (barn) | D5: Nej | E5: B | F5: Deep / Wing | G5: NL | I5: Vest | J5: Badgers | N5: =CountIF('Plan - NL'!$I$8:$P$31,$A5) -> 0 | O5: =COUNTIFS('Plan - NL'!$M$8:$M$31,$A5) -> 0 | P5: =COUNTIFS('Plan - NL'!$N$8:$O$31,$A5) -> 0 | Q5: =COUNTIFS('Plan - NL'!$I$8:$L$31,$A5)+COUNTIFS('Plan - NL'!$P$8:$P$31,$A5) -> 0
A6: OJ | B6: Claus Nordberg Larsen | C6: Ude (skade) | D6: Nej | E6: S | F6: B | G6: NL | H6: 3539 | I6: Vest | J6: Uafhængig | L6: 41817432 | M6: nordberg20@gmail.com | N6: =CountIF('Plan - NL'!$I$8:$P$31,$A6) -> 0 | O6: =COUNTIFS('Plan - NL'!$O$8:$O$31,$A6) -> 0 | P6: =COUNTIFS('Plan - NL'!$M$8:$N$31,$A6) -> 0 | Q6: =COUNTIFS('Plan - NL'!$I$8:$L$31,$A6)+COUNTIFS('Plan - NL'!$P$8:$P$31,$A6) -> 0
A7: EM | B7: Emil Riisgaard | C7: Semi | D7: Nej | E7: B | G7: C | I7: Øst | J7: Uafhængig | L7: 30481382 | M7: emilriisgaard@hotmail.com | N7: =CountIF('Plan - NL'!$I$8:$P$31,$A7) -> 0 | O7: =COUNTIFS('Plan - NL'!$M$8:$M$31,$A7) -> 0 | P7: =COUNTIFS('Plan - NL'!$N$8:$O$31,$A7) -> 0 | Q7: =COUNTIFS('Plan - NL'!$I$8:$L$31,$A7)+COUNTIFS('Plan - NL'!$P$8:$P$31,$A7) -> 0
A8: ER | B8: Erik Rasmussen | C8: NL | D8: Ja | E8: F | F8: S/B | G8: NL | H8: 711 | I8: Øst | J8: Uafhængig | L8: 40824426 | M8: erikrasmussen23@gmail.com | N8: =CountIF('Plan - NL'!$I$8:$P$31,$A8) -> 9 | O8: =COUNTIFS('Plan - NL'!$N$8:$N$31,$A8) -> 5 | P8: =COUNTIFS('Plan - NL'!$M$8:$M$31,$A8) + COUNTIFS('Plan - NL'!$O$8:$O$31,$A8) -> 3 | Q8: =COUNTIFS('Plan - NL'!$I$8:$L$31,$A8)+COUNTIFS('Plan - NL'!$P$8:$P$31,$A8) -> 1
A9: FK | B9: Frank Kristensen | C9: Ude (ELF) | D9: Ja | E9: B | G9: I | H9: 5 | I9: Øst | J9: Uafhængig | L9: 60607240 | M9: fk110871@gmail.com | N9: =CountIF('Plan - NL'!$I$8:$P$31,$A9) -> 1 | O9: =COUNTIFS('Plan - NL'!$M$8:$M$31,$A9) -> 0 | P9: =COUNTIFS('Plan - NL'!$N$8:$O$31,$A9) -> 0 | Q9: =COUNTIFS('Plan - NL'!$I$8:$L$31,$A9)+COUNTIFS('Plan - NL'!$P$8:$P$31,$A9) -> 1
A10: KL | B10: Kim Larsen | C10: NL | D10: Ja | E10: F | F10: S | G10: I | H10: 3274 | I10: Vest | J10: Uafhængig | L10: 23255155 | M10: k.m.larzen@gmail.com | N10: =CountIF('Plan - NL'!$I$8:$P$31,$A10) -> 10 | O10: =COUNTIFS('Plan - NL'!$N$8:$N$31,$A10) -> 9 | P10: =COUNTIFS('Plan - NL'!$M$8:$M$31,$A10) + COUNTIFS('Plan - NL'!$O$8:$O$31,$A10) -> 1 | Q10: =COUNTIFS('Plan - NL'!$I$8:$L$31,$A10)+COUNTIFS('Plan - NL'!$P$8:$P$31,$A10) -> 0
A11: KJ | B11: Kim Johannsen | C11: NL | D11: Ja | E11: F/S | F11: L | G11: I | H11: 2269 | I11: Øst | J11: Uafhængig | L11: 22754529 | M11: kim.johannsen@gmail.com | N11: =CountIF('Plan - NL'!$I$8:$P$31,$A11) -> 8 | O11: =COUNTIFS('Plan - NL'!$N$8:$N$31,$A11) -> 6 | P11: =COUNTIFS('Plan - NL'!$M$8:$M$31,$A11) + COUNTIFS('Plan - NL'!$O$8:$O$31,$A11) -> 2 | Q11: =COUNTIFS('Plan - NL'!$I$8:$L$31,$A11)+COUNTIFS('Plan - NL'!$P$8:$P$31,$A11) -> 0
A12: MM | B12: Martin Mikkelsen | C12: NL | D12: Nej | E12: H/L | F12: Dyb | G12: NL | H12: 628 | I12: Øst | J12: Uafhængig | L12: 26807765 | M12: mrtn.mkklsn@gmail.com | N12: =CountIF('Plan - NL'!$I$8:$P$31,$A12) -> 6 | O12: =COUNTIFS('Plan - NL'!$K$8:$K$31,$A12) -> 6 | P12: =COUNTIFS('Plan - NL'!$L$8:$L$31,$A12) -> 0 | Q12: =COUNTIFS('Plan - NL'!$I$8:$J$31,$A12)+COUNTIFS('Plan - NL'!$M$8:$P$31,$A12) -> 0
A13: JL | B13: Jesper Lytzen | C13: NL | D13: Ja | E13: L | F13: H (F/S) | G13: NL | H13: 16327 | I13: Vest | J13: Uafhængig | L13: 22614222 | M13: lytzen13@gmail.com | N13: =CountIF('Plan - NL'!$I$8:$P$31,$A13) -> 6 | O13: =COUNTIFS('Plan - NL'!$L$8:$L$31,$A13) -> 4 | P13: =COUNTIFS('Plan - NL'!$K$8:$K$31,$A13) -> 2 | Q13: =COUNTIFS('Plan - NL'!$I$8:$J$31,$A13)+COUNTIFS('Plan - NL'!$M$8:$P$31,$A13) -> 0
A14: JK | B14: Jonas Krum | C14: NL | D14: Nej | E14: L | G14: NL | H14: 3536 | I14: Øst | J14: Uafhængig | L14: 53390568 | M14: jonaskrum@gmail.com | N14: =CountIF('Plan - NL'!$I$8:$P$31,$A14) -> 0 | O14: =COUNTIFS('Plan - NL'!$L$8:$L$31,$A14) -> 0 | P14: =COUNTIFS('Plan - NL'!$K$8:$K$31,$A14) -> 0 | Q14: =COUNTIFS('Plan - NL'!$I$8:$J$31,$A14)+COUNTIFS('Plan - NL'!$M$8:$P$31,$A14) -> 0
A15: HP | B15: Hans Peter Roth | C15: NL | D15: Ja | E15: L | G15: NL
A16: MÅ | B16: Mads Åkjær | C16: Ude (ELF) | D16: Nej | E16: S | F16: R | G16: NL | H16: 10257 | I16: Øst | J16: Uafhængig | L16: 51844821 | M16: mads_aakjaer@hotmail.com | N16: =CountIF('Plan - NL'!$I$8:$P$31,$A16) -> 0 | O16: =COUNTIFS('Plan - NL'!$O$8:$O$31,$A16) -> 0 | P16: =COUNTIFS('Plan - NL'!$M$8:$N$31,$A16) -> 0 | Q16: =COUNTIFS('Plan - NL'!$I$8:$L$31,$A16)+COUNTIFS('Plan - NL'!$P$8:$P$31,$A16) -> 0
A17: NI | B17: Niels Ilberg | C17: NL | D17: Nej | E17: L/H | F17: U | G17: I | H17: 1133 | I17: Vest | J17: Uafhængig | L17: 29870710 | M17: niels@ilberg.dk | N17: =CountIF('Plan - NL'!$I$8:$P$31,$A17) -> 4 | O17: =COUNTIFS('Plan - NL'!$L$8:$L$31,$A17) -> 2 | P17: =COUNTIFS('Plan - NL'!$K$8:$K$31,$A17) -> 2 | Q17: =COUNTIFS('Plan - NL'!$I$8:$J$31,$A17)+COUNTIFS('Plan - NL'!$M$8:$P$31,$A17) -> 0
A18: FR | B18: Frank Rasmussen | C18: NL | D18: Nej | E18: R | F18: Anything | G18: I | H18: 484 | I18: Øst | J18: Uafhængig | L18: 20342617 | M18: dommer484@gmail.com | N18: =CountIF('Plan - NL'!$I$8:$P$31,$A18) -> 8 | O18: =COUNTIFS('Plan - NL'!$I$8:$I$31,$A18) -> 8 | P18: =COUNTIFS('Plan - NL'!$J$8:$J$31,$A18) -> 0 | Q18: =COUNTIFS('Plan - NL'!$K$8:$P$31,$A18) -> 0
A19: MC | B19: Mohammed Chatle | C19: Ude | D19: Nej | E19: U | F19: B | G19: NL | H19: 9074 | I19: Vest | J19: Tigers | L19: 51542401 | M19: mohammed780_2@hotmail.com | N19: =CountIF('Plan - NL'!$I$8:$P$31,$A19) -> 0 | O19: =COUNTIFS('Plan - NL'!$M$8:$M$31,$A19) -> 0 | P19: =COUNTIFS('Plan - NL'!$N$8:$O$31,$A19) -> 0 | Q19: =COUNTIFS('Plan - NL'!$I$8:$L$31,$A19)+COUNTIFS('Plan - NL'!$P$8:$P$31,$A19) -> 0
A20: MR | B20: Michael Rahbek | C20: NL | D20: Ja | E20: R | F20: S | G20: I | H20: 7255 | I20: Vest | J20: Uafhængig | L20: 60507214 | M20: michael.g.rahbek@gmail.com | N20: =CountIF('Plan - NL'!$I$8:$P$31,$A20) -> 7 | O20: =COUNTIFS('Plan - NL'!$I$8:$I$31,$A20) -> 6 | P20: =COUNTIFS('Plan - NL'!$J$8:$J$31,$A20) -> 0 | Q20: =COUNTIFS('Plan - NL'!$K$8:$P$31,$A20) -> 1
A21: SR | B21: Søren Rosenlund Pedersen | C21: Mangler | D21: Nej | E21: H | F21: L | H21: 10624 | I21: Øst | J21: Uafhængig | L21: 51501389 | M21: srosenlund88@gmail.com | N21: =CountIF('Plan - NL'!$I$8:$P$31,$A21) -> 0 | O21: =COUNTIFS('Plan - NL'!$K$8:$K$31,$A21) -> 0 | P21: =COUNTIFS('Plan - NL'!$L$8:$L$31,$A21) -> 0 | Q21: =COUNTIFS('Plan - NL'!$I$8:$J$31,$A21)+COUNTIFS('Plan - NL'!$M$8:$P$31,$A21) -> 0
A22: TM | B22: Thomas Myrup | C22: Pause | D22: Ja | E22: B | F22: F/S | G22: NL | H22: 9063 | I22: Vest | J22: Tigers | M22: eyez@eyez.dk | N22: =CountIF('Plan - NL'!$I$8:$P$31,$A22) -> 5 | O22: =COUNTIFS('Plan - NL'!$O$8:$O$31,$A22) -> 5 | P22: =COUNTIFS('Plan - NL'!$M$8:$N$31,$A22) -> 0 | Q22: =COUNTIFS('Plan - NL'!$I$8:$L$31,$A22)+COUNTIFS('Plan - NL'!$P$8:$P$31,$A22) -> 0
A23: TS | B23: Thomas Siggaard | C23: Ude (ELF) | D23: Ja | E23: H/L | F23: U | G23: I | H23: 41 | I23: Øst | J23: Uafhængig | L23: 51618450 | M23: thsiggaard@gmail.com | N23: =CountIF('Plan - NL'!$I$8:$P$31,$A23) -> 5 | O23: =COUNTIFS('Plan - NL'!$K$8:$K$31,$A23) -> 3 | P23: =COUNTIFS('Plan - NL'!$L$8:$L$31,$A23) -> 0 | Q23: =COUNTIFS('Plan - NL'!$I$8:$J$31,$A23)+COUNTIFS('Plan - NL'!$M$8:$P$31,$A23) -> 2
A24: VN | B24: Vincent Nordkov | C24: Ude (ELF) | D24: Ja | E24: U | G24: NL | I24: Øst | J24: Uafhængig | L24: 60677402 | M24: vincentnordkov@hotmail.com | N24: =CountIF('Plan - NL'!$I$8:$P$31,$A24) -> 2 | O24: =COUNTIFS('Plan - NL'!$J$8:$J$31,$A24) -> 0 | P24: =COUNTIFS('Plan - NL'!$I$8:$I$31,$A24) -> 0 | Q24: =COUNTIFS('Plan - NL'!$K$8:$P$31,$A24) -> 2
A25: AR | B25: Asbjørn Rohold | C25: NL | D25: Nej | E25: U | F25: R | G25: NL | I25: Vest | J25: Tigers | N25: =CountIF('Plan - NL'!$I$8:$P$31,$A25) -> 6 | O25: =COUNTIFS('Plan - NL'!$L$8:$L$31,$A25) -> 0 | P25: =COUNTIFS('Plan - NL'!$K$8:$K$31,$A25) -> 0 | Q25: =COUNTIFS('Plan - NL'!$I$8:$J$31,$A25)+COUNTIFS('Plan - NL'!$M$8:$P$31,$A25) -> 6
A26: TB | B26: Thomas Begonja | C26: Mangler
A27: DS | B27: Dennis Svensson | C27: NL | D27: Ja | E27: U | G27: NL
A28: TK | B28: Troels Kristensen | C28: Ude (SGD) | D28: Ja | G28: C
A29: MØ | B29: Martin Møller | C29: Mangler | E29: B
A30: MP | B30: Mark Poulsen | C30: Tilkalder | D30: Nej | E30: Wing | G30: C
A31: RH | B31: Ronnie Hansen | C31: Prospect | D31: Ja | E31: Wing | G31: C
A32: AL | B32: Alex Lind | C32: Prospect | D32: Ja | E32: Wing | G32: C
A33: TO | B33: Tommy Lønstrup Nielsen | D33: Nej | E33: Wing | G33: C
A34: AF | B34: Albert Fosberg | C34: Prospect | D34: Nej | E34: Wing
A35: BT | B35: Bo Thygesen | C35: NL | D35: Ja | G35: NL
A36: KE | B36: Kent Johansen | C36: Prospect | D36: Ja | E36: Wing
G37: Primær | H37: Sekundær
B38: Mangler | C38: =COUNTIF($C$3:$C$35,B38) -> 3 | D38: =COUNTIF($D$3:$D$35,"Ja") -> 16 | F38: R* | G38: =COUNTIF($E$3:$E$35,$F38) -> 2 | H38: =COUNTIF($F$3:$F$35,$F38) -> 2
B39: NL | C39: =COUNTIF($C$3:$C$35,B39) -> 15 | D39: =COUNTIF($D$3:$D$35,"Nej") -> 14 | F39: U* | G39: =COUNTIF($E$3:$E$35,$F39) -> 4 | H39: =COUNTIF($F$3:$F$35,$F39) -> 2
B40: Pause* | C40: =COUNTIF($C$3:$C$35,B40) -> 2 | F40: F* | G40: =COUNTIF($E$3:$E$35,$F40) -> 3 | H40: =COUNTIF($F$3:$F$35,$F40) -> 1
...

Sheet Former Officials
N1: Games
A2: Initialer | B2: Navn | C2: Status | D2: EDK | E2: Primær | F2: Sekundær | G2: Licens | H2: Licens # | I2: Landsdel | J2: Klub | K2: Test | L2: Telefon | M2: Mail | N2: Total | O2: Primary position | P2: In primary group (not primary position) | Q2: Outside primary group
A3: AD | B3: Adam Durucz | C3: Former | D3: Nej | E3: L | I3: Vest | N3: =CountIF('Plan - NL'!$I$8:$P$31,$A3) -> 0 | O3: =COUNTIFS('Plan - NL'!$L$8:$L$31,$A3) -> 0 | P3: =COUNTIFS('Plan - NL'!$K$8:$K$31,$A3) -> 0 | Q3: =COUNTIFS('Plan - NL'!$I$8:$J$31,$A3)+COUNTIFS('Plan - NL'!$M$8:$P$31,$A3) -> 0
A4: CJ | B4: Christian Jørgensen | C4: Former | D4: Nej | E4: U | F4: R | G4: I | H4: 7246 | I4: Øst | J4: Uafhængig | L4: 51248482 | M4: christian@technobabble.dk | N4: =CountIF('Plan - NL'!$I$8:$P$31,$A4) -> 0 | O4: =COUNTIFS('Plan - NL'!$J$8:$J$31,$A4) -> 0 | P4: =COUNTIFS('Plan - NL'!$I$8:$I$31,$A4) -> 0 | Q4: =COUNTIFS('Plan - NL'!$K$8:$P$31,$A4) -> 0
A5: JT | B5: Jeppe Bjerg Thanning | C5: Former | D5: Nej | E5: U | G5: C | H5: 15447 | I5: Vest | J5: 89ers | N5: =CountIF('Plan - NL'!$I$8:$P$31,$A5) -> 0 | O5: =COUNTIFS('Plan - NL'!$J$8:$J$31,$A5) -> 0 | P5: =COUNTIFS('Plan - NL'!$I$8:$I$31,$A5) -> 0 | Q5: =COUNTIFS('Plan - NL'!$K$8:$P$31,$A5) -> 0
A6: KN | B6: Kim Mørch Nørgaard | C6: Former | D6: Nej | E6: H | G6: C | I6: Vest | J6: Stallions | M6: pray@live.dk | N6: =CountIF('Plan - NL'!$I$8:$P$31,$A6) -> 0 | O6: =COUNTIFS('Plan - NL'!$K$8:$K$31,$A6) -> 0 | P6: =COUNTIFS('Plan - NL'!$L$8:$L$31,$A6) -> 0 | Q6: =COUNTIFS('Plan - NL'!$I$8:$J$31,$A6)+COUNTIFS('Plan - NL'!$M$8:$P$31,$A6) -> 0
A7: SK | B7: Slava Kuzmin | C7: Former | D7: Nej | E7: B | N7: =CountIF('Plan - NL'!$I$8:$P$31,$A7) -> 0 | O7: =COUNTIFS('Plan - NL'!$M$8:$M$31,$A7) -> 0 | P7: =COUNTIFS('Plan - NL'!$N$8:$O$31,$A7) -> 0 | Q7: =COUNTIFS('Plan - NL'!$I$8:$L$31,$A7)+COUNTIFS('Plan - NL'!$P$8:$P$31,$A7) -> 0
A8: ST | B8: Søren Stiesen | C8: Former | D8: Nej | E8: L | G8: C | H8: 10548 | I8: Vest | M8: Stisen202@gmail.com | N8: =CountIF('Plan - NL'!$I$8:$P$31,$A8) -> 0 | O8: =COUNTIFS('Plan - NL'!$L$8:$L$31,$A8) -> 0 | P8: =COUNTIFS('Plan - NL'!$K$8:$K$31,$A8) -> 0 | Q8: =COUNTIFS('Plan - NL'!$I$8:$J$31,$A8)+COUNTIFS('Plan - NL'!$M$8:$P$31,$A8) -> 0
A9: UO | B9: Ulf Overbeck | C9: Former | D9: Nej | E9: U | G9: C | H9: 274 | I9: Vest | J9: Uafhængig | L9: 27205364 | M9: airulf@hotmail.com | N9: =CountIF('Plan - NL'!$I$8:$P$31,$A9) -> 0 | O9: =COUNTIFS('Plan - NL'!$J$8:$J$31,$A9) -> 0 | P9: =COUNTIFS('Plan - NL'!$I$8:$I$31,$A9) -> 0 | Q9: =COUNTIFS('Plan - NL'!$K$8:$P$31,$A9) -> 0
G10: Primær | H10: Sekundær
B11: Mangler | C11: =COUNTIF($C$3:$C$9,B11) -> 0 | D11: =COUNTIF($D$3:$D$9,"Ja") -> 0 | F11: R* | G11: =COUNTIF($E$4:$E$9,$F11) -> 0 | H11: =COUNTIF($F$4:$F$9,$F11) -> 1
B12: NL | C12: =COUNTIF($C$3:$C$9,B12) -> 0 | D12: =COUNTIF($D$3:$D$9,"Nej") -> 7 | F12: U* | G12: =COUNTIF($E$4:$E$9,$F12) -> 3 | H12: =COUNTIF($F$4:$F$9,$F12) -> 0
B13: NL (back in) | C13: =COUNTIF($C$3:$C$9,B13) -> 0 | F13: H* | G13: =COUNTIF($E$4:$E$9,$F13) -> 1 | H13: =COUNTIF($F$4:$F$9,$F13) -> 0
B14: Måske pause | C14: =COUNTIF($C$3:$C$9,B14) -> 0 | F14: L* | G14: =COUNTIF($E$4:$E$9,$F14) -> 1 | H14: =COUNTIF($F$4:$F$9,$F14) -> 0
B15: Pause* | C15: =COUNTIF($C$3:$C$9,B15) -> 0 | F15: F* | G15: =COUNTIF($E$4:$E$9,$F15) -> 0 | H15: =COUNTIF($F$4:$F$9,$F15) -> 0
B16: Inde? | C16: =COUNTIF($C$3:$C$9,B16) -> 0 | F16: S* | G16: =COUNTIF($E$4:$E$9,$F16) -> 0 | H16: =COUNTIF($F$4:$F$9,$F16) -> 0
B17: Semi | C17: =COUNTIF($C$3:$C$9,B17) -> 0 | F17: B* | G17: =COUNTIF($E$4:$E$9,$F17) -> 1 | H17: =COUNTIF($F$4:$F$9,$F17) -> 0
B18: Prospect | C18: =COUNTIF($C$3:$C$9,B18) -> 0
B19: Ude* | C19: =COUNTIF($C$3:$C$9,B19) -> 0 | F19: Tidlig plan
B20: Tilkalder | C20: =COUNTIF($C$3:$C$9,B20) -> 0 | F20: Prospects med i første runde

Sheet Plan - NL + 1. Div backup
A1: Kampnr. | B1: Runde | C1: Dag | D1: Dato | E1: Måned | F1: Tidspunkt | G1: Hjemme | H1: Ude | I1: R | J1: U | K1: H | L1: L | M1: B | N1: F | O1: S | P1: C | Q1: Note | S1: 1s | T1: 2s | U1: 3s | V1: Taske | W1: Taske IND | X1: Taske UD | Y1: Betaling | Z1: Video | AA1: Gennemseer | AC1: Game start | AD1: Game end | AE1: Video Exchanged. | AF1: Game time (easy) | AG1: Intercut time (min) | AH1: Exchange of Breakdown data | AI1: Return of break down data | AK1: Upload time | AL1: Breakdown time | AM1: Game time
B2: 2 | C2: Lørdag | D2: 15 | E2: maj | F2: 0.58333333 | G2: Badgers | H2: Hurricanes | I2: MR | J2: JT | K2: NI | L2: JL | M2: AT | N2: KL | O2: OJ | R2: Stille med 2-3 NL dommere | S2: =COUNTIF('Status data'!$A2:$H2,"1") -> 1 | T2: =COUNTIF('Status data'!$A2:$H2,"2") -> 2 | U2: =COUNTIF('Status data'!$A2:$H2,"3") -> 0 | AF2: =HOUR(AD2-AC2)&"h"&minute(AD2-AC2)&"m" -> 0h0m | AK2: =AE2-#REF! -> #REF! | AL2: =AH2-#REF! -> #REF! | AM2: =#REF!-AC2 -> #REF!
B3: 2 | C3: Lørdag | D3: 15 | E3: maj | F3: 0.58333333 | G3: Oaks | H3: Rebels | I3: CJ | J3: VN | L3: JK | M3: EM | N3: JE | O3: KJ | Q3: KEEP | R3: NL plan ud, 1. div næste uge | S3: =COUNTIF('Status data'!$A3:$H3,"1") -> 0 | T3: =COUNTIF('Status data'!$A3:$H3,"2") -> 0 | U3: =COUNTIF('Status data'!$A3:$H3,"3") -> 0 | AC3: 44059.585 | AD3: 44059.681 | AE3: 44060.033 | AF3: =HOUR(AD3-AC3)&"h"&minute(AD3-AC3)&"m" -> 2h18m | AK3: =AE3-AD3 -> 0.35208333 | AL3: =AH3-AD3 -> -44059.681 | AM3: =AD3-AC3 -> 0.095833333
B4: 2 | C4: Søndag | D4: 16 | E4: maj | F4: 0.58333333 | G4: Knights | H4: Demons / Wolfpack | I4: FR | J4: CJ | K4: TS | L4: (JK) | M4: FK | N4: JE | O4: MÅ | Q4: KEEP | R4: KBH fuldt crew | S4: =COUNTIF('Status data'!$A4:$H4,"1") -> 0 | T4: =COUNTIF('Status data'!$A4:$H4,"2") -> 0 | U4: =COUNTIF('Status data'!$A4:$H4,"3") -> 0 | AF4: =HOUR(AD4-AC4)&"h"&minute(AD4-AC4)&"m" -> 0h0m | AK4: =AE4-AD4 -> 0 | AL4: =AH4-AD4 -> 0 | AM4: =AD4-AC4 -> 0
B5: 3 | C5: Lørdag | D5: 22 | E5: maj | F5: 0.79166667 | G5: Towers | H5: 89ers | I5: FK | J5: CJ | K5: TS | L5: JK | M5: EM | N5: KJ | O5: MÅ | P5: FR | R5: Behold plan, til DU møde | S5: =COUNTIF('Status data'!$A5:$H5,"1") -> 0 | T5: =COUNTIF('Status data'!$A5:$H5,"2") -> 0 | U5: =COUNTIF('Status data'!$A5:$H5,"3") -> 0 | AF5: =HOUR(AD5-AC5)&"h"&minute(AD5-AC5)&"m" -> 0h0m | AK5: =AH5-AD5 -> 0 | AL5: =AH5-AD5 -> 0 | AM5: =AD5-AC5 -> 0
B6: 3 | C6: Søndag | D6: 23 | E6: maj | F6: 0.58333333 | G6: Dragons | H6: Tigers | J6: AR | L6: JL | M6: (AT) | N6: KL | O6: OJ | Q6: AT over - langt? | R6: 1. Div; supervisors fx - ikke 7 | S6: =COUNTIF('Status data'!$A6:$H6,"1") -> 2 | T6: =COUNTIF('Status data'!$A6:$H6,"2") -> 1 | U6: =COUNTIF('Status data'!$A6:$H6,"3") -> 1
B7: 3 | C7: Søndag | D7: 23 | E7: maj | F7: 0.58333333 | G7: Rebels | H7: Monarchs | I7: CJ | J7: VN | L7: (JK) | M7: AT | N7: KJ | O7: MÅ | S7: =COUNTIF('Status data'!$A7:$H7,"1") -> 0 | T7: =COUNTIF('Status data'!$A7:$H7,"2") -> 0 | U7: =COUNTIF('Status data'!$A7:$H7,"3") -> 0
B8: 4 | C8: Lørdag | D8: 29 | E8: maj | F8: 0.58333333 | G8: Spartans | H8: Knights | I8: FR | J8: CJ | K8: TS | L8: JK | M8: FK | N8: KJ | O8: MÅ | P8: (EM) | Q8: KEEP, men overvej hvem der kan flyttes til d. 29. i Vejle | S8: =COUNTIF('Status data'!$A8:$H8,"1") -> 0 | T8: =COUNTIF('Status data'!$A8:$H8,"2") -> 0 | U8: =COUNTIF('Status data'!$A8:$H8,"3") -> 0
B9: 4 | C9: Lørdag | D9: 29 | E9: maj | F9: 0.79166667 | G9: Razorbacks | H9: Towers | I9: MR | J9: VN | K9: NI | L9: TB | M9: FK | N9: KL | O9: JE | P9: AT | Q9: Bil fra øst over under alle omstændigheder (B/deep/U). Hvis 8 på SNL; FK B, AT C. AT her | S9: =COUNTIF('Status data'!$A9:$H9,"1") -> 0 | T9: =COUNTIF('Status data'!$A9:$H9,"2") -> 0 | U9: =COUNTIF('Status data'!$A9:$H9,"3") -> 0
B10: 5 | C10: Lørdag | D10: 5 | E10: juni | F10: 0.58333333 | G10: Demons / Wolfpack | H10: Oaks | I10: FR | J10: CJ | K10: TS | L10: JK | M10: FK | N10: KJ | O10: MÅ | Q10: KEEP | S10: =COUNTIF('Status data'!$A10:$H10,"1") -> 0 | T10: =COUNTIF('Status data'!$A10:$H10,"2") -> 0 | U10: =COUNTIF('Status data'!$A10:$H10,"3") -> 0
B11: 5 | C11: Lørdag | D11: 5 | E11: juni | F11: 0.79166667 | G11: 89ers | H11: Gold Diggers | I11: MR | J11: JT | K11: NI | L11: JL | M11: AT | N11: KL | O11: OJ | S11: =COUNTIF('Status data'!$A11:$H11,"1") -> 0 | T11: =COUNTIF('Status data'!$A11:$H11,"2") -> 0 | U11: =COUNTIF('Status data'!$A11:$H11,"3") -> 0
B12: 6 | C12: Lørdag | D12: 12 | E12: juni | F12: 0.58333333 | G12: Knights | H12: Monarchs | I12: FR | J12: VN | K12: TS | L12: JK | M12: EM | N12: JE | O12: KJ | Q12: KEEP, men prioriterer NL kampen i Jylland | S12: =COUNTIF('Status data'!$A12:$H12,"1") -> 4 | T12: =COUNTIF('Status data'!$A12:$H12,"2") -> 0 | U12: =COUNTIF('Status data'!$A12:$H12,"3") -> 1
B13: 6 | C13: Lørdag | D13: 12 | E13: juni | F13: 0.79166667 | G13: 89ers | H13: Razorbacks | I13: MR | J13: AR | K13: NI | L13: FR/JE | M13: FK | N13: KL | O13: OJ | P13: AT | Q13: TB? JE, FR, CJ | S13: =COUNTIF('Status data'!$A13:$H13,"1") -> 0 | T13: =COUNTIF('Status data'!$A13:$H13,"2") -> 0 | U13: =COUNTIF('Status data'!$A13:$H13,"3") -> 0
B14: 7 | C14: Lørdag | D14: 19 | E14: juni | F14: 0.58333333 | G14: Gold Diggers | H14: Towers | I14: FR | J14: VN | K14: TS | L14: JK | M14: EM | N14: JE | O14: MÅ | S14: =COUNTIF('Status data'!$A14:$H14,"1") -> 0 | T14: =COUNTIF('Status data'!$A14:$H14,"2") -> 0 | U14: =COUNTIF('Status data'!$A14:$H14,"3") -> 0 | AF14: =HOUR(AD14-AC14)&"h"&minute(AD14-AC14)&"m" -> 0h0m | AK14: =AE14-AD14 -> 0 | AL14: =AH14-AD14 -> 0 | AM14: =AD14-AC14 -> 0
B15: 7 | C15: Søndag | D15: 20 | E15: juni | F15: 0.58333333 | G15: Musketeers | H15: Tigers | I15: MR | J15: AR | K15: NI | L15: (JL) | M15: (AT) | N15: (KJ) | O15: OJ | S15: =COUNTIF('Status data'!$A15:$H15,"1") -> 0 | T15: =COUNTIF('Status data'!$A15:$H15,"2") -> 0 | U15: =COUNTIF('Status data'!$A15:$H15,"3") -> 0 | AC15: 44086.585 | AD15: 44086.692 | AE15: 44087.043 | AF15: =HOUR(AD15-AC15)&"h"&minute(AD15-AC15)&"m" -> 2h34m | AK15: =AE15-AD15 -> 0.35138889 | AL15: =AH15-AD15 -> -44086.692 | AM15: =AD15-AC15 -> 0.10694444
B16: 8 | C16: Lørdag | D16: 26 | E16: juni | F16: 0.58333333 | G16: Gold Diggers | H16: Razorbacks | I16: FR | J16: CJ | K16: TS | L16: JK | M16: FK | N16: KJ | O16: MÅ | S16: =COUNTIF('Status data'!$A16:$H16,"1") -> 0 | T16: =COUNTIF('Status data'!$A16:$H16,"2") -> 0 | U16: =COUNTIF('Status data'!$A16:$H16,"3") -> 0 | AF16: =HOUR(AD16-AC16)&"h"&minute(AD16-AC16)&"m" -> 0h0m | AK16: =AE16-AD16 -> 0
B17: 9 | C17: Lørdag | D17: 14 | E17: august | F17: 0.58333333 | G17: Tigers | H17: Hurricanes | S17: =COUNTIF('Status data'!$A17:$H17,"1") -> 0 | T17: =COUNTIF('Status data'!$A17:$H17,"2") -> 0 | U17: =COUNTIF('Status data'!$A17:$H17,"3") -> 0
B18: 9 | C18: Lørdag | D18: 14 | E18: august | F18: 0.58333333 | G18: Gold Diggers | H18: 89ers | S18: =COUNTIF(#REF!,"1") -> 0 | T18: =COUNTIF(#REF!,"2") -> 0 | U18: =COUNTIF(#REF!,"3") -> 0
B19: 9 | C19: Søndag | D19: 15 | E19: august | F19: 0.58333333 | G19: Oaks | H19: Knights | S19: =COUNTIF('Status data'!$A18:$H18,"1") -> 0 | T19: =COUNTIF('Status data'!$A18:$H18,"2") -> 0 | U19: =COUNTIF('Status data'!$A18:$H18,"3") -> 0
B20: 10 | C20: Lørdag | D20: 21 | E20: august | F20: 0.79166667 | G20: Towers | H20: Razorbacks | S20: =COUNTIF('Status data'!$A19:$H19,"1") -> 2 | T20: =COUNTIF('Status data'!$A19:$H19,"2") -> 2 | U20: =COUNTIF('Status data'!$A19:$H19,"3") -> 0
B21: 10 | C21: Søndag | D21: 22 | E21: august | F21: 0.58333333 | G21: Badgers | H21: Musketeers | S21: =COUNTIF('Status data'!$A20:$H20,"1") -> 0 | T21: =COUNTIF('Status data'!$A20:$H20,"2") -> 0 | U21: =COUNTIF('Status data'!$A20:$H20,"3") -> 0
B22: 11 | C22: Lørdag | D22: 28 | E22: august | F22: 0.58333333 | G22: 89ers | H22: Towers | S22: =COUNTIF('Status data'!$A21:$H21,"1") -> 0 | T22: =COUNTIF('Status data'!$A21:$H21,"2") -> 0 | U22: =COUNTIF('Status data'!$A21:$H21,"3") -> 0
B23: 11 | C23: Lørdag | D23: 28 | E23: august | F23: 0.58333333 | G23: Razorbacks | H23: Gold Diggers | S23: =COUNTIF('Status data'!$A22:$H22,"1") -> 0 | T23: =COUNTIF('Status data'!$A22:$H22,"2") -> 0 | U23: =COUNTIF('Status data'!$A22:$H22,"3") -> 0
B24: 11 | C24: Søndag | D24: 29 | E24: august | F24: 0.58333333 | G24: Monarchs | H24: Demons / Wolfpack | S24: =COUNTIF('Status data'!$A23:$H23,"1") -> 0 | T24: =COUNTIF('Status data'!$A23:$H23,"2") -> 0 | U24: =COUNTIF('Status data'!$A23:$H23,"3") -> 0 | AF24: =HOUR(AD24-AC24)&"h"&minute(AD24-AC24)&"m" -> 0h0m | AK24: =AE24-AD24 -> 0
B25: 12 | C25: Lørdag | D25: 4 | E25: september | F25: 0.58333333 | G25: Dragons | H25: Rebels | S25: =COUNTIF('Status data'!$A24:$H24,"1") -> 0 | T25: =COUNTIF('Status data'!$A24:$H24,"2") -> 0 | U25: =COUNTIF('Status data'!$A24:$H24,"3") -> 0
B26: 12 | C26: Lørdag | D26: 4 | E26: september | F26: 0.79166667 | G26: Towers | H26: Gold Diggers | S26: =COUNTIF('Status data'!$A25:$H25,"1") -> 0 | T26: =COUNTIF('Status data'!$A25:$H25,"2") -> 0 | U26: =COUNTIF('Status data'!$A25:$H25,"3") -> 0
B27: 13 | C27: Lørdag | D27: 11 | E27: september | F27: 0.58333333 | G27: Demons / Wolfpack | H27: Badgers | S27: =COUNTIF('Status data'!$A26:$H26,"1") -> 0 | T27: =COUNTIF('Status data'!$A26:$H26,"2") -> 0 | U27: =COUNTIF('Status data'!$A26:$H26,"3") -> 0
B28: 13 | C28: Lørdag | D28: 11 | E28: september | F28: 0.79166667 | G28: Razorbacks | H28: 89ers | S28: =COUNTIF('Status data'!$A27:$H27,"1") -> 0 | T28: =COUNTIF('Status data'!$A27:$H27,"2") -> 0 | U28: =COUNTIF('Status data'!$A27:$H27,"3") -> 0
B29: 13 | C29: Søndag | D29: 12 | E29: september | F29: 0.58333333 | G29: Monarchs | H29: Oaks | S29: =COUNTIF('Status data'!$A28:$H28,"1") -> 0 | T29: =COUNTIF('Status data'!$A28:$H28,"2") -> 0 | U29: =COUNTIF('Status data'!$A28:$H28,"3") -> 0
A30: Semi 1 | B30: 14 | C30: Lørdag | D30: 18 | E30: september | S30: =COUNTIF('Status data'!$A29:$H29,"1") -> 0 | T30: =COUNTIF('Status data'!$A29:$H29,"2") -> 0 | U30: =COUNTIF('Status data'!$A29:$H29,"3") -> 0
A31: Semi 2 | B31: 14 | C31: Søndag | D31: 18 | E31: september | S31: =COUNTIF('Status data'!$A30:$H30,"1") -> 0 | T31: =COUNTIF('Status data'!$A30:$H30,"2") -> 0 | U31: =COUNTIF('Status data'!$A30:$H30,"3") -> 0
A32: 3rd place | B32: 15 | C32: Lørdag | D32: 2 | E32: oktober | S32: =COUNTIF('Status data'!$A31:$H31,"1") -> 0 | T32: =COUNTIF('Status data'!$A31:$H31,"2") -> 0 | U32: =COUNTIF('Status data'!$A31:$H31,"3") -> 0
A33: Mermaid Bowl | B33: 15 | C33: Lørdag | D33: 2 | E33: oktober | S33: =COUNTIF('Status data'!$A32:$H32,"1") -> 0 | T33: =COUNTIF('Status data'!$A32:$H32,"2") -> 0 | U33: =COUNTIF('Status data'!$A32:$H32,"3") -> 0
B34: 4 | C34: Lørdag/Søndag | D34: 29/30 | E34: maj | F34: 0.58333333 | G34: Hurricanes | H34: Musketeers
A36: Initialer
A37: Anders Tronier | B37: AT | C37: =COUNTIF($I$2:$O$31,B37) -> 3
A38: Brian Baagøe Andersen | B38: BA | C38: =COUNTIF($I$2:$O$31,B38) -> 0 | Q38: =DATA!I65 | W38: =SUM(Y1:Y31) -> 0 | X38: 2 | Y38: medium
A39: Bo Thygesen | B39: BT | C39: =COUNTIF($I$2:$O$31,B39) -> 0 | Q39: =DATA!I66 | V39: AVERAGE | W39: =AVERAGE(Y2:Y33) -> #DIV/0! | X39: 1 | Y39: bad
A40: Christian Jørgensen | B40: CJ | C40: =COUNTIF($I$2:$O$31,B40) -> 7 | Q40: =DATA!I67 | V40: MEDIAN | W40: =MEDIAN(Y2:Y33) -> #NUM! | X40: s | Y40: stats
A41: Emil Riisgaard | B41: EM | C41: =COUNTIF($I$2:$O$31,B41) -> 4 | V41: PROJECTED 1 | W41: =W39*40 -> #DIV/0! | X41: e | Y41: endzone
...

Sheet 2021 status
A1: Navn | B1: Initialer | C1: Yes / No | D1: Commitment | E1: Position | F1: Level
A2: Adam Durucz | B2: AD | C2: No | D2: Tilbage i Ungarn | E2: L | F2: 3
A3: Asbjørn Rohold | B3: AR | C3: Yes | D3: Ok, vil gerne lære mere | E3: U | F3: 3
A4: Anders Tronier | B4: AT | C4: Yes | D4: OK | E4: B | F4: 2
A5: Brian Andersen | B5: BA | C5: Måske | D5: Bachelor + Far | E5: B | F5: 3
A6: Christian Jørgensen | B6: CJ | C6: No | D6: Rejser til USA | E6: U | F6: 1
A7: Emil Riisgaard | B7: EM | C7: Yes | D7: Ok, så meget som muligt | E7: B | F7: 2
A8: Erik Rasmussen | B8: ER | C8: Yes | D8: Pause forår, knæ | E8: F | F8: 2
A9: Frank Kristensen | B9: FK | C9: Yes | D9: OK, så meget som muligt | E9: B | F9: 1
A10: Frank Rasmussen | B10: FR | C10: Yes | D10: OK, så meget som muligt | E10: R | F10: 1
A11: Jeppe Holm | B11: JE | C11: Yes | D11: Ok, ja til ansvar | E11: F | F11: 1
A12: Jonas Krum | B12: JK | C12: Måske | D12: OK | E12: L | F12: 1
A13: Jesper Lytzen | B13: JL | C13: Yes | D13: Ok, så meget som muligt | E13: L | F13: 2
... A25: Søren Rosenlund | B25: SR | C25: Yes | D25: Ok, men ikke meget | E25: H | F25: 1
A26: Thomas Begonja | B26: TB | C26: Yes | D26: #N/A | E26: L | F26: 3
A27: Thomas Myrup | B27: TM | C27: Yes | D27: Tilbage | E27: F | F27: 3
A28: Thomas Siggaard | B28: TS | C28: Yes | D28: #N/A | E28: H | F28: 1
A29: Ulf Overbeck | B29: UO | C29: No | D29: Ude | E29: U
A30: Vincent Nordkov | B30: VN | C30: Yes | D30: OK, så meget som muligt | E30: U | F30: 2
A31: Søren Skovsgaard Berthelsen | B31: SB | D31: ? | F31: 3

Sheet Status data
A1: R | B1: U | C1: H | D1: L | E1: B | F1: F | G1: S | H1: C
A2: =VLOOKUP('Plan - NL'!I8,'2021 status'!$B$2:$F$30,5,FALSE) -> #N/A | B2: =VLOOKUP('Plan - NL'!J8,'2021 status'!$B$2:$F$30,5,FALSE) -> #N/A | C2: =VLOOKUP('Plan - NL'!K8,'2021 status'!$B$2:$F$30,5,FALSE) -> #N/A | D2: =VLOOKUP('Plan - NL'!L8,'2021 status'!$B$2:$F$30,5,FALSE) -> 1 | E2: =VLOOKUP('Plan - NL'!M8,'2021 status'!$B$2:$F$30,5,FALSE) -> #N/A | F2: =VLOOKUP('Plan - NL'!N8,'2021 status'!$B$2:$F$30,5,FALSE) -> 2 | G2: =VLOOKUP('Plan - NL'!O8,'2021 status'!$B$2:$F$30,5,FALSE) -> 2 | H2: =VLOOKUP('Plan - NL'!P8,'2021 status'!$B$2:$F$30,5,FALSE) -> #N/A
A3: =VLOOKUP(#REF!,'2021 status'!$B$2:$F$30,5,FALSE) -> #REF! | B3: =VLOOKUP(#REF!,'2021 status'!$B$2:$F$30,5,FALSE) -> #REF! | C3: =VLOOKUP(#REF!,'2021 status'!$B$2:$F$30,5,FALSE) -> #REF! | D3: =VLOOKUP(#REF!,'2021 status'!$B$2:$F$30,5,FALSE) -> #REF! | E3: =VLOOKUP(#REF!,'2021 status'!$B$2:$F$30,5,FALSE) -> #REF! | F3: =VLOOKUP(#REF!,'2021 status'!$B$2:$F$30,5,FALSE) -> #REF! | G3: =VLOOKUP(#REF!,'2021 status'!$B$2:$F$30,5,FALSE) -> #REF! | H3: =VLOOKUP(#REF!,'2021 status'!$B$2:$F$30,5,FALSE) -> #REF!
A4: =VLOOKUP(#REF!,'2021 status'!$B$2:$F$30,5,FALSE) -> #REF! | B4: =VLOOKUP(#REF!,'2021 status'!$B$2:$F$30,5,FALSE) -> #REF! | C4: =VLOOKUP(#REF!,'2021 status'!$B$2:$F$30,5,FALSE) -> #REF! | D4: =VLOOKUP(#REF!,'2021 status'!$B$2:$F$30,5,FALSE) -> #REF! | E4: =VLOOKUP(#REF!,'2021 status'!$B$2:$F$30,5,FALSE) -> #REF! | F4: =VLOOKUP(#REF!,'2021 status'!$B$2:$F$30,5,FALSE) -> #REF! | G4: =VLOOKUP(#REF!,'2021 status'!$B$2:$F$30,5,FALSE) -> #REF! | H4: =VLOOKUP(#REF!,'2021 status'!$B$2:$F$30,5,FALSE) -> #REF!
A5: =VLOOKUP(#REF!,'2021 status'!$B$2:$F$30,5,FALSE) -> #REF! | B5: =VLOOKUP(#REF!,'2021 status'!$B$2:$F$30,5,FALSE) -> #REF! | C5: =VLOOKUP(#REF!,'2021 status'!$B$2:$F$30,5,FALSE) -> #REF! | D5: =VLOOKUP(#REF!,'2021 status'!$B$2:$F$30,5,FALSE) -> #REF! | E5: =VLOOKUP(#REF!,'2021 status'!$B$2:$F$30,5,FALSE) -> #REF! | F5: =VLOOKUP(#REF!,'2021 status'!$B$2:$F$30,5,FALSE) -> #REF! | G5: =VLOOKUP(#REF!,'2021 status'!$B$2:$F$30,5,FALSE) -> #REF! | H5: =VLOOKUP(#REF!,'2021 status'!$B$2:$F$30,5,FALSE) -> #REF!
A6: =VLOOKUP('Plan - NL'!I9,'2021 status'!$B$2:$F$30,5,FALSE) -> 1 | B6: =VLOOKUP('Plan - NL'!J9,'2021 status'!$B$2:$F$30,5,FALSE) -> #N/A | C6: =VLOOKUP('Plan - NL'!K9,'2021 status'!$B$2:$F$30,5,FALSE) -> #N/A | D6: =VLOOKUP('Plan - NL'!L9,'2021 status'!$B$2:$F$30,5,FALSE) -> 2 | E6: =VLOOKUP('Plan - NL'!M9,'2021 status'!$B$2:$F$30,5,FALSE) -> #N/A | F6: =VLOOKUP('Plan - NL'!N9,'2021 status'!$B$2:$F$30,5,FALSE) -> 1 | G6: =VLOOKUP('Plan - NL'!O9,'2021 status'!$B$2:$F$30,5,FALSE) -> 3 | H6: =VLOOKUP('Plan - NL'!P9,'2021 status'!$B$2:$F$30,5,FALSE) -> #N/A
A7: =VLOOKUP(#REF!,'2021 status'!$B$2:$F$30,5,FALSE) -> #REF! | B7: =VLOOKUP(#REF!,'2021 status'!$B$2:$F$30,5,FALSE) -> #REF! | C7: =VLOOKUP(#REF!,'2021 status'!$B$2:$F$30,5,FALSE) -> #REF! | D7: =VLOOKUP(#REF!,'2021 status'!$B$2:$F$30,5,FALSE) -> #REF! | E7: =VLOOKUP(#REF!,'2021 status'!$B$2:$F$30,5,FALSE) -> #REF! | F7: =VLOOKUP(#REF!,'2021 status'!$B$2:$F$30,5,FALSE) -> #REF! | G7: =VLOOKUP(#REF!,'2021 status'!$B$2:$F$30,5,FALSE) -> #REF! | H7: =VLOOKUP(#REF!,'2021 status'!$B$2:$F$30,5,FALSE) -> #REF!
A8: =VLOOKUP(#REF!,'2021 status'!$B$2:$F$30,5,FALSE) -> #REF! | B8: =VLOOKUP(#REF!,'2021 status'!$B$2:$F$30,5,FALSE) -> #REF! | C8: =VLOOKUP(#REF!,'2021 status'!$B$2:$F$30,5,FALSE) -> #REF! | D8: =VLOOKUP(#REF!,'2021 status'!$B$2:$F$30,5,FALSE) -> #REF! | E8: =VLOOKUP(#REF!,'2021 status'!$B$2:$F$30,5,FALSE) -> #REF! | F8: =VLOOKUP(#REF!,'2021 status'!$B$2:$F$30,5,FALSE) -> #REF! | G8: =VLOOKUP(#REF!,'2021 status'!$B$2:$F$30,5,FALSE) -> #REF! | H8: =VLOOKUP(#REF!,'2021 status'!$B$2:$F$30,5,FALSE) -> #REF!
A9: =VLOOKUP(#REF!,'2021 status'!$B$2:$F$30,5,FALSE) -> #REF! | B9: =VLOOKUP(#REF!,'2021 status'!$B$2:$F$30,5,FALSE) -> #REF! | C9: =VLOOKUP(#REF!,'2021 status'!$B$2:$F$30,5,FALSE) -> #REF! | D9: =VLOOKUP(#REF!,'2021 status'!$B$2:$F$30,5,FALSE) -> #REF! | E9: =VLOOKUP(#REF!,'2021 status'!$B$2:$F$30,5,FALSE) -> #REF! | F9: =VLOOKUP(#REF!,'2021 status'!$B$2:$F$30,5,FALSE) -> #REF! | G9: =VLOOKUP(#REF!,'2021 status'!$B$2:$F$30,5,FALSE) -> #REF! | H9: =VLOOKUP(#REF!,'2021 status'!$B$2:$F$30,5,FALSE) -> #REF!
A10: =VLOOKUP(#REF!,'2021 status'!$B$2:$F$30,5,FALSE) -> #REF! | B10: =VLOOKUP(#REF!,'2021 status'!$B$2:$F$30,5,FALSE) -> #REF! | C10: =VLOOKUP(#REF!,'2021 status'!$B$2:$F$30,5,FALSE) -> #REF! | D10: =VLOOKUP(#REF!,'2021 status'!$B$2:$F$30,5,FALSE) -> #REF! | E10: =VLOOKUP(#REF!,'2021 status'!$B$2:$F$30,5,FALSE) -> #REF! | F10: =VLOOKUP(#REF!,'2021 status'!$B$2:$F$30,5,FALSE) -> #REF! | G10: =VLOOKUP(#REF!,'2021 status'!$B$2:$F$30,5,FALSE) -> #REF! | H10: =VLOOKUP(#REF!,'2021 status'!$B$2:$F$30,5,FALSE) -> #REF!
A11: =VLOOKUP(#REF!,'2021 status'!$B$2:$F$30,5,FALSE) -> #REF! | B11: =VLOOKUP(#REF!,'2021 status'!$B$2:$F$30,5,FALSE) -> #REF! | C11: =VLOOKUP(#REF!,'2021 status'!$B$2:$F$30,5,FALSE) -> #REF! | D11: =VLOOKUP(#REF!,'2021 status'!$B$2:$F$30,5,FALSE) -> #REF! | E11: =VLOOKUP(#REF!,'2021 status'!$B$2:$F$30,5,FALSE) -> #REF! | F11: =VLOOKUP(#REF!,'2021 status'!$B$2:$F$30,5,FALSE) -> #REF! | G11: =VLOOKUP(#REF!,'2021 status'!$B$2:$F$30,5,FALSE) -> #REF! | H11: =VLOOKUP(#REF!,'2021 status'!$B$2:$F$30,5,FALSE) -> #REF!
A12: =VLOOKUP('Plan - NL'!I20,'2021 status'!$B$2:$F$30,5,FALSE) -> 1 | B12: =VLOOKUP('Plan - NL'!J20,'2021 status'!$B$2:$F$30,5,FALSE) -> #N/A | C12: =VLOOKUP('Plan - NL'!K20,'2021 status'!$B$2:$F$30,5,FALSE) -> 1 | D12: =VLOOKUP('Plan - NL'!L20,'2021 status'!$B$2:$F$30,5,FALSE) -> #N/A | E12: =VLOOKUP('Plan - NL'!M20,'2021 status'!$B$2:$F$30,5,FALSE) -> 1 | F12: =VLOOKUP('Plan - NL'!N20,'2021 status'!$B$2:$F$30,5,FALSE) -> 1 | G12: =VLOOKUP('Plan - NL'!O20,'2021 status'!$B$2:$F$30,5,FALSE) -> 3 | H12: =VLOOKUP('Plan - NL'!P20,'2021 status'!$B$2:$F$30,5,FALSE) -> #N/A
A13: =VLOOKUP(#REF!,'2021 status'!$B$2:$F$30,5,FALSE) -> #REF! | B13: =VLOOKUP(#REF!,'2021 status'!$B$2:$F$30,5,FALSE) -> #REF! | C13: =VLOOKUP(#REF!,'2021 status'!$B$2:$F$30,5,FALSE) -> #REF! | D13: =VLOOKUP(#REF!,'2021 status'!$B$2:$F$30,5,FALSE) -> #REF! | E13: =VLOOKUP(#REF!,'2021 status'!$B$2:$F$30,5,FALSE) -> #REF! | F13: =VLOOKUP(#REF!,'2021 status'!$B$2:$F$30,5,FALSE) -> #REF! | G13: =VLOOKUP(#REF!,'2021 status'!$B$2:$F$30,5,FALSE) -> #REF! | H13: =VLOOKUP(#REF!,'2021 status'!$B$2:$F$30,5,FALSE) -> #REF!
A14: =VLOOKUP(#REF!,'2021 status'!$B$2:$F$30,5,FALSE) -> #REF! | B14: =VLOOKUP(#REF!,'2021 status'!$B$2:$F$30,5,FALSE) -> #REF! | C14: =VLOOKUP(#REF!,'2021 status'!$B$2:$F$30,5,FALSE) -> #REF! | D14: =VLOOKUP(#REF!,'2021 status'!$B$2:$F$30,5,FALSE) -> #REF! | E14: =VLOOKUP(#REF!,'2021 status'!$B$2:$F$30,5,FALSE) -> #REF! | F14: =VLOOKUP(#REF!,'2021 status'!$B$2:$F$30,5,FALSE) -> #REF! | G14: =VLOOKUP(#REF!,'2021 status'!$B$2:$F$30,5,FALSE) -> #REF! | H14: =VLOOKUP(#REF!,'2021 status'!$B$2:$F$30,5,FALSE) -> #REF!
A15: =VLOOKUP(#REF!,'2021 status'!$B$2:$F$30,5,FALSE) -> #REF! | B15: =VLOOKUP(#REF!,'2021 status'!$B$2:$F$30,5,FALSE) -> #REF! | C15: =VLOOKUP(#REF!,'2021 status'!$B$2:$F$30,5,FALSE) -> #REF! | D15: =VLOOKUP(#REF!,'2021 status'!$B$2:$F$30,5,FALSE) -> #REF! | E15: =VLOOKUP(#REF!,'2021 status'!$B$2:$F$30,5,FALSE) -> #REF! | F15: =VLOOKUP(#REF!,'2021 status'!$B$2:$F$30,5,FALSE) -> #REF! | G15: =VLOOKUP(#REF!,'2021 status'!$B$2:$F$30,5,FALSE) -> #REF! | H15: =VLOOKUP(#REF!,'2021 status'!$B$2:$F$30,5,FALSE) -> #REF!
A16: =VLOOKUP(#REF!,'2021 status'!$B$2:$F$30,5,FALSE) -> #REF! | B16: =VLOOKUP(#REF!,'2021 status'!$B$2:$F$30,5,FALSE) -> #REF! | C16: =VLOOKUP(#REF!,'2021 status'!$B$2:$F$30,5,FALSE) -> #REF! | D16: =VLOOKUP(#REF!,'2021 status'!$B$2:$F$30,5,FALSE) -> #REF! | E16: =VLOOKUP(#REF!,'2021 status'!$B$2:$F$30,5,FALSE) -> #REF! | F16: =VLOOKUP(#REF!,'2021 status'!$B$2:$F$30,5,FALSE) -> #REF! | G16: =VLOOKUP(#REF!,'2021 status'!$B$2:$F$30,5,FALSE) -> #REF! | H16: =VLOOKUP(#REF!,'2021 status'!$B$2:$F$30,5,FALSE) -> #REF!
A17: =VLOOKUP(#REF!,'2021 status'!$B$2:$F$30,5,FALSE) -> #REF! | B17: =VLOOKUP(#REF!,'2021 status'!$B$2:$F$30,5,FALSE) -> #REF! | C17: =VLOOKUP(#REF!,'2021 status'!$B$2:$F$30,5,FALSE) -> #REF! | D17: =VLOOKUP(#REF!,'2021 status'!$B$2:$F$30,5,FALSE) -> #REF! | E17: =VLOOKUP(#REF!,'2021 status'!$B$2:$F$30,5,FALSE) -> #REF! | F17: =VLOOKUP(#REF!,'2021 status'!$B$2:$F$30,5,FALSE) -> #REF! | G17: =VLOOKUP(#REF!,'2021 status'!$B$2:$F$30,5,FALSE) -> #REF! | H17: =VLOOKUP(#REF!,'2021 status'!$B$2:$F$30,5,FALSE) -> #REF!
A18: =VLOOKUP(#REF!,'2021 status'!$B$2:$F$30,5,FALSE) -> #REF! | B18: =VLOOKUP(#REF!,'2021 status'!$B$2:$F$30,5,FALSE) -> #REF! | C18: =VLOOKUP(#REF!,'2021 status'!$B$2:$F$30,5,FALSE) -> #REF! | D18: =VLOOKUP(#REF!,'2021 status'!$B$2:$F$30,5,FALSE) -> #REF! | E18: =VLOOKUP(#REF!,'2021 status'!$B$2:$F$30,5,FALSE) -> #REF! | F18: =VLOOKUP(#REF!,'2021 status'!$B$2:$F$30,5,FALSE) -> #REF! | G18: =VLOOKUP(#REF!,'2021 status'!$B$2:$F$30,5,FALSE) -> #REF! | H18: =VLOOKUP(#REF!,'2021 status'!$B$2:$F$30,5,FALSE) -> #REF!
A19: =VLOOKUP('Plan - NL'!I25,'2021 status'!$B$2:$F$30,5,FALSE) -> 1 | B19: =VLOOKUP('Plan - NL'!J25,'2021 status'!$B$2:$F$30,5,FALSE) -> #N/A | C19: =VLOOKUP('Plan - NL'!K25,'2021 status'!$B$2:$F$30,5,FALSE) -> #N/A | D19: =VLOOKUP('Plan - NL'!L25,'2021 status'!$B$2:$F$30,5,FALSE) -> #N/A | E19: =VLOOKUP('Plan - NL'!M25,'2021 status'!$B$2:$F$30,5,FALSE) -> 1 | F19: =VLOOKUP('Plan - NL'!N25,'2021 status'!$B$2:$F$30,5,FALSE) -> 2 | G19: =VLOOKUP('Plan - NL'!O25,'2021 status'!$B$2:$F$30,5,FALSE) -> 2 | H19: =VLOOKUP('Plan - NL'!P25,'2021 status'!$B$2:$F$30,5,FALSE) -> #N/A
A20: =VLOOKUP(#REF!,'2021 status'!$B$2:$F$30,5,FALSE) -> #REF! | B20: =VLOOKUP(#REF!,'2021 status'!$B$2:$F$30,5,FALSE) -> #REF! | C20: =VLOOKUP(#REF!,'2021 status'!$B$2:$F$30,5,FALSE) -> #REF! | D20: =VLOOKUP(#REF!,'2021 status'!$B$2:$F$30,5,FALSE) -> #REF! | E20: =VLOOKUP(#REF!,'2021 status'!$B$2:$F$30,5,FALSE) -> #REF! | F20: =VLOOKUP(#REF!,'2021 status'!$B$2:$F$30,5,FALSE) -> #REF! | G20: =VLOOKUP(#REF!,'2021 status'!$B$2:$F$30,5,FALSE) -> #REF! | H20: =VLOOKUP(#REF!,'2021 status'!$B$2:$F$30,5,FALSE) -> #REF!
A21: =VLOOKUP(#REF!,'2021 status'!$B$2:$F$30,5,FALSE) -> #REF! | B21: =VLOOKUP(#REF!,'2021 status'!$B$2:$F$30,5,FALSE) -> #REF! | C21: =VLOOKUP(#REF!,'2021 status'!$B$2:$F$30,5,FALSE) -> #REF! | D21: =VLOOKUP(#REF!,'2021 status'!$B$2:$F$30,5,FALSE) -> #REF! | E21: =VLOOKUP(#REF!,'2021 status'!$B$2:$F$30,5,FALSE) -> #REF! | F21: =VLOOKUP(#REF!,'2021 status'!$B$2:$F$30,5,FALSE) -> #REF! | G21: =VLOOKUP(#REF!,'2021 status'!$B$2:$F$30,5,FALSE) -> #REF! | H21: =VLOOKUP(#REF!,'2021 status'!$B$2:$F$30,5,FALSE) -> #REF!
A22: =VLOOKUP(#REF!,'2021 status'!$B$2:$F$30,5,FALSE) -> #REF! | B22: =VLOOKUP(#REF!,'2021 status'!$B$2:$F$30,5,FALSE) -> #REF! | C22: =VLOOKUP(#REF!,'2021 status'!$B$2:$F$30,5,FALSE) -> #REF! | D22: =VLOOKUP(#REF!,'2021 status'!$B$2:$F$30,5,FALSE) -> #REF! | E22: =VLOOKUP(#REF!,'2021 status'!$B$2:$F$30,5,FALSE) -> #REF! | F22: =VLOOKUP(#REF!,'2021 status'!$B$2:$F$30,5,FALSE) -> #REF! | G22: =VLOOKUP(#REF!,'2021 status'!$B$2:$F$30,5,FALSE) -> #REF! | H22: =VLOOKUP(#REF!,'2021 status'!$B$2:$F$30,5,FALSE) -> #REF!

Sheet 2020 status
A1: Initials | B1: Yes / No | C1: Commitment | D1: Position | E1: Level
A2: AD | B2: Yes | D2: L | E2: 3
A3: AR | B3: Yes | D3: S | E3: 3
A4: AT | B4: Yes | D4: B | E4: 2
A5: BA | B5: Yes | D5: B | E5: 3
A6: CJ | B6: Yes | C6: Som 2019 | D6: U | E6: 1
A7: EM | B7: Yes | C7: Orlov studie | D7: B | E7: 2
A8: ER | B8: Yes | C8: Virker mere klar end tidligere | D8: F | E8: 2
A9: FK | B9: Yes | D9: B | E9: 1
A10: FR | B10: Yes | D10: R | E10: 1
A11: JE | B11: Yes | D11: F | E11: 1
A12: JK | B12: Yes | D12: L | E12: 1
A13: JL | B13: Yes | D13: L | E13: 2
A14: JT | B14: Pause | C14: Far marts | D14: U
A15: KJ | B15: Yes | D15: F | E15: 2
A16: KL | B16: Yes | D16: F | E16: 1
A17: KN | B17: Yes | D17: H | E17: 3
A18: MC | B18: Yes | D18: B | E18: 3
A19: MM | B19: Yes | D19: L | E19: 1
A20: MR | B20: Yes | D20: R | E20: 1
A21: MÅ | B21: Yes | D21: S | E21: 2
A22: NI | B22: Yes | D22: L | E22: 1
A23: OJ | B23: Yes | D23: S | E23: 2
A24: SK | B24: Yes | C24: Might only be available until May | D24: B | E24: 2
A25: SR | B25: Yes | D25: H | E25: 1
A26: TB | B26: Yes | D26: L | E26: 3
A27: TM | B27: Yes | D27: F | E27: 3
A28: TS | B28: Yes | D28: H | E28: 1
A29: UO | B29: No | D29: U
A30: VN | B30: Yes | D30: U | E30: 2

Sheet Tasks
A1: NL tasks
B2: 1. person | C2: 2. person
A3: Kamppapirer | B3: KL
A4: Kamptasker | B4: JK | C4: KJ
A5: Radioer | B5: KK | C5: SR
A6: Assignmemt | B6: MM | C6: KL / JE
A7: Gennemseening af kampe | B7: SR | C7: KL
A8: Deeps | B8: FK
A9: Wings | B9: MM
A10: Ref / Ump | B10: MM
A11: Kontakt til DAFF | B11: MM

Sheet Stats
H1: Dommerudgifter | I1: Gennemsnit | K1: Upload tid | L1: Gennemsnit | M1: MXl | N1: Grænse | O1: Sluttidspunkt | P1: Varighed | Q1: Varighed af kamp | R1: MXl for varighed
A2: =#REF! -> #REF! | B2: =#REF! -> #REF! | C2: =#REF! -> #REF! | D2: =#REF! -> #REF! | E2: =#REF! -> #REF! | F2: =#REF! -> #REF! | G2: =C2&" "&B2 -> #REF! | H2: =#REF! -> #REF! | I2: =AVERAGE(H$2:H$51) -> #REF! | J2: =#REF! -> #REF! | K2: =IF(DAY(J2)>30,24+HOUR(J2)+MINUTE(J2)/60,HOUR(J2)+MINUTE(J2)/60) -> #REF! | L2: =AVERAGE(K$2:K$51) -> #REF! | M2: 24 | N2: 36 | O2: =#REF! -> #REF! | P2: =IF(O2>0,O2-E2,"") -> #REF! | Q2: =HOUR(P2)+MINUTE(P2)/60 -> #REF! | R2: =HOUR("02.23.00")+MINUTE("02.23.00")/60 -> 2.3833333 | S2: =AVERAGE(Q2:Q61) -> #REF! | T2: =O2-E2 -> #REF! | U2: =IF(DAY(T2)>30,24+HOUR(T2)+MINUTE(T2)/60,HOUR(T2)+MINUTE(T2)/60) -> #REF!
A3: =#REF! -> #REF! | B3: =#REF! -> #REF! | C3: =#REF! -> #REF! | D3: =#REF! -> #REF! | E3: =#REF! -> #REF! | F3: =#REF! -> #REF! | G3: =C3&" "&B3 -> #REF! | H3: =#REF! -> #REF! | I3: =AVERAGE(H$2:H$51) -> #REF! | J3: =#REF! -> #REF! | K3: =IF(DAY(J3)>30,24+HOUR(J3)+MINUTE(J3)/60,HOUR(J3)+MINUTE(J3)/60) -> #REF! | L3: =AVERAGE(K$2:K$51) -> #REF! | M3: 24 | N3: 36 | O3: =#REF! -> #REF! | P3: =IF(O3>0,O3-E3,"") -> #REF! | Q3: =HOUR(P3)+MINUTE(P3)/60 -> #REF! | R3: =HOUR("02.23.00")+MINUTE("02.23.00")/60 -> 2.3833333 | T3: =O3-E3 -> #REF! | U3: =IF(DAY(T3)>30,24+HOUR(T3)+MINUTE(T3)/60,HOUR(T3)+MINUTE(T3)/60) -> #REF!
A4: =#REF! -> #REF! | B4: =#REF! -> #REF! | C4: =#REF! -> #REF! | D4: =#REF! -> #REF! | E4: =#REF! -> #REF! | F4: =#REF! -> #REF! | G4: =C4&" "&B4 -> #REF! | H4: =#REF! -> #REF! | I4: =AVERAGE(H$2:H$51) -> #REF! | J4: =#REF! -> #REF! | K4: =IF(DAY(J4)>30,24+HOUR(J4)+MINUTE(J4)/60,HOUR(J4)+MINUTE(J4)/60) -> #REF! | L4: =AVERAGE(K$2:K$51) -> #REF! | M4: 24 | N4: 36 | O4: =#REF! -> #REF! | P4: =IF(O4>0,O4-E4,"") -> #REF! | Q4: =HOUR(P4)+MINUTE(P4)/60 -> #REF! | R4: =HOUR("02.23.00")+MINUTE("02.23.00")/60 -> 2.3833333 | T4: =O4-E4 -> #REF! | U4: =IF(DAY(T4)>30,24+HOUR(T4)+MINUTE(T4)/60,HOUR(T4)+MINUTE(T4)/60) -> #REF!
A5: =#REF! -> #REF! | B5: =#REF! -> #REF! | C5: =#REF! -> #REF! | D5: =#REF! -> #REF! | E5: =#REF! -> #REF! | F5: =#REF! -> #REF! | G5: =C5&" "&B5 -> #REF! | H5: =#REF! -> #REF! | I5: =AVERAGE(H$2:H$51) -> #REF! | J5: =#REF! -> #REF! | K5: =IF(DAY(J5)>30,24+HOUR(J5)+MINUTE(J5)/60,HOUR(J5)+MINUTE(J5)/60) -> #REF! | L5: =AVERAGE(K$2:K$51) -> #REF! | M5: 24 | N5: 36 | O5: =#REF! -> #REF! | P5: =IF(O5>0,O5-E5,"") -> #REF! | Q5: =HOUR(P5)+MINUTE(P5)/60 -> #REF! | R5: =HOUR("02.23.00")+MINUTE("02.23.00")/60 -> 2.3833333 | T5: =O5-E5 -> #REF! | U5: =IF(DAY(T5)>30,24+HOUR(T5)+MINUTE(T5)/60,HOUR(T5)+MINUTE(T5)/60) -> #REF!
A6: =#REF! -> #REF! | B6: =#REF! -> #REF! | C6: =#REF! -> #REF! | D6: =#REF! -> #REF! | E6: =#REF! -> #REF! | F6: =#REF! -> #REF! | G6: =C6&" "&B6 -> #REF! | H6: =#REF! -> #REF! | I6: =AVERAGE(H$2:H$51) -> #REF! | J6: =#REF! -> #REF! | K6: =IF(DAY(J6)>30,24+HOUR(J6)+MINUTE(J6)/60,HOUR(J6)+MINUTE(J6)/60) -> #REF! | L6: =AVERAGE(K$2:K$51) -> #REF! | M6: 24 | N6: 36 | O6: =#REF! -> #REF! | P6: =IF(O6>0,O6-E6,"") -> #REF! | Q6: =HOUR(P6)+MINUTE(P6)/60 -> #REF! | R6: =HOUR("02.23.00")+MINUTE("02.23.00")/60 -> 2.3833333 | T6: =O6-E6 -> #REF! | U6: =IF(DAY(T6)>30,24+HOUR(T6)+MINUTE(T6)/60,HOUR(T6)+MINUTE(T6)/60) -> #REF!
A7: =#REF! -> #REF! | B7: =#REF! -> #REF! | C7: =#REF! -> #REF! | D7: =#REF! -> #REF! | E7: =#REF! -> #REF! | F7: =#REF! -> #REF! | G7: =C7&" "&B7 -> #REF! | H7: =#REF! -> #REF! | I7: =AVERAGE(H$2:H$51) -> #REF! | J7: =#REF! -> #REF! | K7: =IF(DAY(J7)>30,24+HOUR(J7)+MINUTE(J7)/60,HOUR(J7)+MINUTE(J7)/60) -> #REF! | L7: =AVERAGE(K$2:K$51) -> #REF! | M7: 24 | N7: 36 | O7: =#REF! -> #REF! | P7: =IF(O7>0,O7-E7,"") -> #REF! | Q7: =HOUR(P7)+MINUTE(P7)/60 -> #REF! | R7: =HOUR("02.23.00")+MINUTE("02.23.00")/60 -> 2.3833333 | T7: =O7-E7 -> #REF! | U7: =IF(DAY(T7)>30,24+HOUR(T7)+MINUTE(T7)/60,HOUR(T7)+MINUTE(T7)/60) -> #REF!
