Workbook

Sheet Plan - NL
B1: Runde | C1: Dag | D1: Dato | E1: Måned | F1: Tidspunkt | G1: Hjemme | H1: Ude | I1: R | J1: U | K1: H | L1: L | M1: B | N1: F | O1: S | P1: C | Q1: Note | R1: Antal tilmeldte VK 25-03 23:47 | S1: 1s | T1: 2s | U1: 3s | V1: Taske | W1: Taske IND | X1: Taske UD | Y1: Betaling | Z1: Video | AA1: Gennemseer | AB1: GameID | AC1: Game start | AD1: Game end | AE1: Video Exchanged. | AF1: Game time (easy) | AG1: Intercut time (min) | AH1: Exchange of Breakdown data | AI1: Return of break down data | AK1: Upload time | AL1: Breakdown time | AM1: Game time
A2: Vedligeholdende | B2: 0 | C2: Lørdag | D2: 29 | E2: Marts | F2: 0.58333333 | G2: Tigers | H2: Wolves | I2: NI | J2: AR | K2: BT | Q2: OBS! Spilles i Aalborg - Klubcrew: Selvdømmer | R2: 1
A3: Vedligeholdende | B3: 0 | C3: Lørdag | D3: 29 | E3: Marts | F3: 0.58333333 | G3: Oaks | H3: Hurricanes | I3: FR | J3: VN | K3: AT | L3: EL | Q3: Klubcrew: Towers | R3: 5
A4: Vedligeholdende | B4: 0 | C4: Søndag | D4: 30 | E4: Marts | F4: 0.58333333 | G4: Towers | H4: Razorbacks | I4: DS | J4: FK | K4: HP | L4: VN | Q4: Klubcrew: Raptors | R4: 0
A5: Vedligeholdende | B5: 1 | C5: Lørdag | D5: 5 | E5: April | F5: 0.58333333 | G5: Razorbacks | H5: Demons | I5: JL | J5: AR | K5: NI | L5: MR | Q5: Klubcrew: Tigers | R5: 0
A6: Vedligeholdende | B6: 1 | C6: Søndag | D6: 6 | E6: April | F6: 0.58333333 | G6: Oaks | H6: Tigers | I6: KJ | J6: JK | K6: FR | L6: HP | Q6: Klubcrew: Demons | R6: 0
A7: NL | B7: 2 | C7: Lørdag | D7: 12 | E7: April | F7: 0.54166667 | G7: Tigers | H7: 89ers | I7: FR | J7: Felix Kastulski | K7: VN | L7: Daniel Kasper | M7: BT | N7: ER | O7: KJ | AB7: =D7&E7&"-"&G7&"-v-"&H7 -> 12April-Tigers-v-89ers
A8: NL | B8: 2 | C8: Søndag | D8: 13 | E8: April | F8: 0.54166667 | G8: Oaks | H8: Razorbacks | I8: DS | J8: VN | K8: JK | L8: JE + RH | M8: AT | N8: EL | O8: HP | AB8: =D8&E8&"-"&G8&"-v-"&H8 -> 13April-Oaks-v-Razorbacks
A9: NL | B9: 4 | C9: Søndag | D9: 27 | E9: April | F9: 0.54166667 | G9: Razorbacks | H9: 89ers | I9: Mats Schwieger | J9: Simon Brüggeman | K9: JL | L9: Matthis Trost | M9: EL | N9: KJ | O9: ER | AB9: =D9&E9&"-"&G9&"-v-"&H9 -> 27April-Razorbacks-v-89ers
A10: NL | B10: 4 | C10: Søndag | D10: 27 | E10: April | F10: 0.54166667 | G10: Tigers | H10: Gold Diggers | I10: DS | J10: AR | K10: TO | L10: FR | M10: BT | N10: KL | O10: AT | Q10: Flyttet fra Søllerød | AB10: =D10&E10&"-"&G10&"-v-"&H10 -> 27April-Tigers-v-Gold Diggers
A11: NL | B11: 5 | C11: Fredag | D11: 2 | E11: Maj | F11: 0.79166667 | G11: Oaks | H11: Towers | I11: JK | J11: DS | K11: MM | L11: FR | M11: JE | N11: KJ | O11: ER | S11: =COUNTIF('Status data'!$A5:$H5,"1") -> 0 | T11: =COUNTIF('Status data'!$A5:$H5,"2") -> 0 | U11: =COUNTIF('Status data'!$A5:$H5,"3") -> 0 | AB11: =D11&E11&"-"&G11&"-v-"&H11 -> 2Maj-Oaks-v-Towers
A12: NL | B12: 6 | C12: Lørdag | D12: 10 | E12: Maj | F12: 0.54166667 | G12: 89ers | H12: Oaks | I12: MR | J12: AR | K12: JL | L12: AL | M12: BT | N12: KL | O12: HP | S12: =COUNTIF('Status data'!$A6:$H6,"1") -> 2 | T12: =COUNTIF('Status data'!$A6:$H6,"2") -> 1 | U12: =COUNTIF('Status data'!$A6:$H6,"3") -> 1 | AB12: =D12&E12&"-"&G12&"-v-"&H12 -> 10Maj-89ers-v-Oaks
A13: NL | B13: 6 | C13: Søndag | D13: 11 | E13: Maj | F13: 0.54166667 | G13: Gold Diggers | H13: Tigers | I13: FK | J13: DS | K13: MM | L13: VN | M13: AT | N13: KJ | O13: EL | Q13: Flyttet fra Aarhus. TV-kamp | S13: =COUNTIF('Status data'!$A7:$H7,"1") -> 0 | T13: =COUNTIF('Status data'!$A7:$H7,"2") -> 0 | U13: =COUNTIF('Status data'!$A7:$H7,"3") -> 0 | AB13: =D13&E13&"-"&G13&"-v-"&H13 -> 11Maj-Gold Diggers-v-Tigers
A14: NL | B14: 8 | C14: Lørdag | D14: 24 | E14: Maj | F14: 0.54166667 | G14: Oaks | H14: Tigers | I14: JE | J14: DS | K14: MM | L14: AL | M14: KJ | N14: TK | O14: ER | S14: =COUNTIF('Status data'!$A8:$H8,"1") -> 0 | T14: =COUNTIF('Status data'!$A8:$H8,"2") -> 0 | U14: =COUNTIF('Status data'!$A8:$H8,"3") -> 0 | AB14: =D14&E14&"-"&G14&"-v-"&H14 -> 24Maj-Oaks-v-Tigers
A15: NL | B15: 8 | C15: Søndag | D15: 25 | E15: Maj | F15: 0.54166667 | G15: Razorbacks | H15: Gold Diggers | I15: MR | J15: DS | K15: JL | L15: HP | M15: BT | N15: KL | O15: FR | S15: =COUNTIF('Status data'!$A9:$H9,"1") -> 0 | T15: =COUNTIF('Status data'!$A9:$H9,"2") -> 0 | U15: =COUNTIF('Status data'!$A9:$H9,"3") -> 0 | AB15: =D15&E15&"-"&G15&"-v-"&H15 -> 25Maj-Razorbacks-v-Gold Diggers | AF15: =HOUR(AD15-AC15)&"h"&minute(AD15-AC15)&"m" -> 0h0m | AK15: =AE15-AD15 -> 0
A16: NL | B16: 9 | C16: Lørdag | D16: 31 | E16: Maj | F16: 0.54166667 | G16: 89ers | H16: Towers | I16: MR | J16: AR | K16: TS | L16: FR | M16: BT | N16: KL | O16: KJ | Q16: TV-kamp | S16: =COUNTIF('Status data'!$A10:$H10,"1") -> 0 | T16: =COUNTIF('Status data'!$A10:$H10,"2") -> 0 | U16: =COUNTIF('Status data'!$A10:$H10,"3") -> 0 | AB16: =D16&E16&"-"&G16&"-v-"&H16 -> 31Maj-89ers-v-Towers
A17: NL | B17: 10 | C17: Lørdag | D17: 7 | E17: Juni | F17: 0.54166667 | G17: Gold Diggers | H17: 89ers | I17: JE | J17: DS | K17: TS | L17: HP | M17: FR | N17: ER | O17: KJ | S17: =COUNTIF('Status data'!$A11:$H11,"1") -> 0 | T17: =COUNTIF('Status data'!$A11:$H11,"2") -> 0 | U17: =COUNTIF('Status data'!$A11:$H11,"3") -> 0 | AB17: =D17&E17&"-"&G17&"-v-"&H17 -> 7Juni-Gold Diggers-v-89ers
A18: NL | B18: 10 | C18: Søndag | D18: 8 | E18: Juni | F18: 0.58333333 | G18: Razorbacks | H18: Oaks | I18: DS | J18: AR | K18: NI | L18: JL | M18: EL | N18: KL | O18: TK | Q18: TV-kamp | S18: =COUNTIF('Status data'!$A12:$H12,"1") -> 0 | T18: =COUNTIF('Status data'!$A12:$H12,"2") -> 0 | U18: =COUNTIF('Status data'!$A12:$H12,"3") -> 0 | AB18: =D18&E18&"-"&G18&"-v-"&H18 -> 8Juni-Razorbacks-v-Oaks
A19: NL | B19: 12 | C19: Søndag | D19: 22 | E19: Juni | F19: 0.54166667 | G19: Tigers | H19: Razorbacks | I19: MR | J19: AR | K19: NI | L19: JL | M19: BT | N19: KL | Q19: TV-kamp | T19: =COUNTIF('Status data'!$A13:$H13,"1") -> 0 | U19: =COUNTIF('Status data'!$A13:$H13,"2") -> 0 | AB19: =D19&E19&"-"&G19&"-v-"&H19 -> 22Juni-Tigers-v-Razorbacks
A20: NL | B20: 12 | C20: Søndag | D20: 22 | E20: Juni | F20: 0.54166667 | G20: Gold Diggers | H20: Towers | I20: FR | J20: DS | K20: MM | L20: HP | M20: JE | N20: ER | O20: KJ | AB20: =D20&E20&"-"&G20&"-v-"&H20 -> 22Juni-Gold Diggers-v-Towers
A21: NL | B21: 17 | C21: Lørdag | D21: 23 | E21: August | F21: 0.54166667 | G21: Towers | H21: Tigers | AB21: =D21&E21&"-"&G21&"-v-"&H21 -> 23August-Towers-v-Tigers
A22: NL | B22: 17 | C22: Søndag | D22: 24 | E22: August | F22: 0.54166667 | G22: 89ers | H22: Razorbacks | S22: =COUNTIF('Status data'!$A14:$H14,"1") -> 0 | T22: =COUNTIF('Status data'!$A14:$H14,"2") -> 0 | U22: =COUNTIF('Status data'!$A14:$H14,"3") -> 0 | AB22: =D22&E22&"-"&G22&"-v-"&H22 -> 24August-89ers-v-Razorbacks
A23: NL | B23: 17 | C23: Søndag | D23: 24 | E23: August | F23: 0.54166667 | G23: Gold Diggers | H23: Oaks | AB23: =D23&E23&"-"&G23&"-v-"&H23 -> 24August-Gold Diggers-v-Oaks
A24: NL | B24: 18 | C24: Lørdag | D24: 30 | E24: August | F24: 0.54166667 | G24: 89ers | H24: Gold Diggers | Q24: Muligvis TV-kamp | S24: =COUNTIF('Status data'!$A17:$H17,"1") -> 0 | T24: =COUNTIF('Status data'!$A17:$H17,"2") -> 0 | U24: =COUNTIF('Status data'!$A17:$H17,"3") -> 0 | AB24: =D24&E24&"-"&G24&"-v-"&H24 -> 30August-89ers-v-Gold Diggers
A25: NL | B25: 18 | C25: Søndag | D25: 31 | E25: August | F25: 0.54166667 | G25: Towers | H25: Razorbacks | AB25: =D25&E25&"-"&G25&"-v-"&H25 -> 31August-Towers-v-Razorbacks
A26: NL | B26: 18 | C26: Søndag | D26: 31 | E26: August | F26: 0.54166667 | G26: Tigers | H26: Oaks | S26: =COUNTIF('Status data'!$A18:$H18,"1") -> 0 | T26: =COUNTIF('Status data'!$A18:$H18,"2") -> 0 | U26: =COUNTIF('Status data'!$A18:$H18,"3") -> 0 | AB26: =D26&E26&"-"&G26&"-v-"&H26 -> 31August-Tigers-v-Oaks
A27: NL | B27: 20 | C27: Fredag | D27: 12 | E27: September | F27: TBD | G27: Towers | H27: Gold Diggers | Q27: TV-kamp | AB27: =D27&E27&"-"&G27&"-v-"&H27 -> 12September-Towers-v-Gold Diggers
A28: NL | B28: 20 | C28: Lørdag | D28: 13 | E28: September | F28: 0.54166667 | G28: Oaks | H28: 89ers | S28: =COUNTIF('Status data'!$A20:$H20,"1") -> 0 | T28: =COUNTIF('Status data'!$A20:$H20,"2") -> 0 | U28: =COUNTIF('Status data'!$A20:$H20,"3") -> 0 | AB28: =D28&E28&"-"&G28&"-v-"&H28 -> 13September-Oaks-v-89ers
A29: NL | B29: 20 | C29: Søndag | D29: 14 | E29: September | F29: 0.54166667 | G29: Razorbacks | H29: Tigers | S29: =COUNTIF('Status data'!$A23:$H23,"1") -> 0 | T29: =COUNTIF('Status data'!$A23:$H23,"2") -> 0 | U29: =COUNTIF('Status data'!$A23:$H23,"3") -> 0 | AB29: =D29&E29&"-"&G29&"-v-"&H29 -> 14September-Razorbacks-v-Tigers
A30: NL | B30: 22 | C30: Lørdag | D30: 27 | E30: September | F30: TBD | G30: Semi | AB30: =D30&E30&"-"&G30&"-v-"&H30 -> 27September-Semi-v-
A31: NL | B31: 22 | C31: Lørdag | D31: 27 | E31: September | F31: TBD | G31: Semi | AB31: =D31&E31&"-"&G31&"-v-"&H31 -> 27September-Semi-v-
A32: NL | B32: 23 | C32: Lørdag | D32: 4 | E32: Oktober | F32: TBD | G32: Mermaid Bowl | AB32: =D32&E32&"-"&G32&"-v-"&H32 -> 4Oktober-Mermaid Bowl-v-
Q34: U17 NM, uge 42 @ København - Onsdag + Lørdag
A36: Navn | B36: Initialer | C36: Kurser | D36: NL forår | E36: Vest forår | F36: Øst forår | G36: Assignment Forår | H36: NL efterår (grundspil) | I36: LL Efterår | J36: NL totalt (grundspil) | K36: In-stribes Total (grundspil)
A37: Michael Rahbek | B37: MR | C37: =IF($A37="","",SUM(($A$2:$A$32="Vedligeholdende")*($I$2:$P$32=$B37))) -> #VALUE! | D37: =IF($A37="","",SUM(($A$2:$A$20="NL")*($I$2:$P$20=$B37))) -> #VALUE! | E37: =IF($A37="","",SUM(($G$7:$G$20="Razorbacks")*($I$7:$P$20=$B37))+SUM(($G$7:$G$20="Tigers")*($I$7:$P$20=$B37))+SUM(($G$7:$G$20="89ers")*($I$7:$P$20=$B37))) -> #VALUE! | F37: =IF($A37="","",SUM(($G$7:$G$20="Oaks")*($I$7:$P$20=$B37))+SUM(($G$7:$G$20="Gold Diggers")*($I$7:$P$20=$B37))+SUM(($G$7:$G$20="Towers")*($I$7:$P$20=$B37))) -> #VALUE! | G37: =IF($A37="","",C37+D37) -> #VALUE! | H37: =IF($A37="","",SUM(($A$21:$A$29="NL")*($I$21:$P$29=$B37))) -> #VALUE! | I37: =IF($A37="","",COUNTIF($I$21:$P$29,$B37)-H37) -> #VALUE! | J37: =IF($A37="","",SUM(($A$2:$A$29="NL")*($I$2:$P$29=$B37))) -> #VALUE! | K37: =IF($A37="","",COUNTIF($I$2:$P$29,$B37)-C37) -> #VALUE!
A38: Frank Rasmussen | B38: FR | C38: =IF($A38="","",SUM(($A$2:$A$32="Vedligeholdende")*($I$2:$P$32=$B38))) -> #VALUE! | D38: =IF($A38="","",SUM(($A$2:$A$20="NL")*($I$2:$P$20=$B38))) -> #VALUE! | E38: =IF($A38="","",SUM(($G$7:$G$20="Razorbacks")*($I$7:$P$20=$B38))+SUM(($G$7:$G$20="Tigers")*($I$7:$P$20=$B38))+SUM(($G$7:$G$20="89ers")*($I$7:$P$20=$B38))) -> #VALUE! | F38: =IF($A38="","",SUM(($G$7:$G$20="Oaks")*($I$7:$P$20=$B38))+SUM(($G$7:$G$20="Gold Diggers")*($I$7:$P$20=$B38))+SUM(($G$7:$G$20="Towers")*($I$7:$P$20=$B38))) -> #VALUE! | G38: =IF($A38="","",C38+D38) -> #VALUE! | H38: =IF($A38="","",SUM(($A$21:$A$29="NL")*($I$21:$P$29=$B38))) -> #VALUE! | I38: =IF($A38="","",COUNTIF($I$21:$P$29,$B38)-H38) -> #VALUE! | J38: =IF($A38="","",SUM(($A$2:$A$29="NL")*($I$2:$P$29=$B38))) -> #VALUE! | K38: =IF($A38="","",COUNTIF($I$2:$P$29,$B38)-C38) -> #VALUE! | R38: =DATA!I65 | W38: =SUM(Y1:Y28) -> 0 | X38: 2 | Y38: medium
A39: Frank Kristensen | B39: FK | C39: =IF($A39="","",SUM(($A$2:$A$32="Vedligeholdende")*($I$2:$P$32=$B39))) -> #VALUE! | D39: =IF($A39="","",SUM(($A$2:$A$20="NL")*($I$2:$P$20=$B39))) -> #VALUE! | E39: =IF($A39="","",SUM(($G$7:$G$20="Razorbacks")*($I$7:$P$20=$B39))+SUM(($G$7:$G$20="Tigers")*($I$7:$P$20=$B39))+SUM(($G$7:$G$20="89ers")*($I$7:$P$20=$B39))) -> #VALUE! | F39: =IF($A39="","",SUM(($G$7:$G$20="Oaks")*($I$7:$P$20=$B39))+SUM(($G$7:$G$20="Gold Diggers")*($I$7:$P$20=$B39))+SUM(($G$7:$G$20="Towers")*($I$7:$P$20=$B39))) -> #VALUE! | G39: =IF($A39="","",C39+D39) -> #VALUE! | H39: =IF($A39="","",SUM(($A$21:$A$29="NL")*($I$21:$P$29=$B39))) -> #VALUE! | I39: =IF($A39="","",COUNTIF($I$21:$P$29,$B39)-H39) -> #VALUE! | J39: =IF($A39="","",SUM(($A$2:$A$29="NL")*($I$2:$P$29=$B39))) -> #VALUE! | K39: =IF($A39="","",COUNTIF($I$2:$P$29,$B39)-C39) -> #VALUE!
C40: =IF($A40="","",SUM(($A$2:$A$32="Vedligeholdende")*($I$2:$P$32=$B40))) | D40: =IF($A40="","",SUM(($A$2:$A$20="NL")*($I$2:$P$20=$B40))) | E40: =IF($A40="","",SUM(($G$7:$G$20="Razorbacks")*($I$7:$P$20=$B40))+SUM(($G$7:$G$20="Tigers")*($I$7:$P$20=$B40))+SUM(($G$7:$G$20="89ers")*($I$7:$P$20=$B40))) | F40: =IF($A40="","",SUM(($G$7:$G$20="Oaks")*($I$7:$P$20=$B40))+SUM(($G$7:$G$20="Gold Diggers")*($I$7:$P$20=$B40))+SUM(($G$7:$G$20="Towers")*($I$7:$P$20=$B40))) | G40: =IF($A40="","",C40+D40) | H40: =IF($A40="","",SUM(($A$21:$A$29="NL")*($I$21:$P$29=$B40))) | I40: =IF($A40="","",COUNTIF($I$21:$P$29,$B40)-H40) | J40: =IF($A40="","",SUM(($A$2:$A$29="NL")*($I$2:$P$29=$B40))) | K40: =IF($A40="","",COUNTIF($I$2:$P$29,$B40)-C40)
A41: Asbjørn Rohold | B41: AR | C41: =IF($A41="","",SUM(($A$2:$A$32="Vedligeholdende")*($I$2:$P$32=$B41))) -> #VALUE! | D41: =IF($A41="","",SUM(($A$2:$A$20="NL")*($I$2:$P$20=$B41))) -> #VALUE! | E41: =IF($A41="","",SUM(($G$7:$G$20="Razorbacks")*($I$7:$P$20=$B41))+SUM(($G$7:$G$20="Tigers")*($I$7:$P$20=$B41))+SUM(($G$7:$G$20="89ers")*($I$7:$P$20=$B41))) -> #VALUE! | F41: =IF($A41="","",SUM(($G$7:$G$20="Oaks")*($I$7:$P$20=$B41))+SUM(($G$7:$G$20="Gold Diggers")*($I$7:$P$20=$B41))+SUM(($G$7:$G$20="Towers")*($I$7:$P$20=$B41))) -> #VALUE! | G41: =IF($A41="","",C41+D41) -> #VALUE! | H41: =IF($A41="","",SUM(($A$21:$A$29="NL")*($I$21:$P$29=$B41))) -> #VALUE! | I41: =IF($A41="","",COUNTIF($I$21:$P$29,$B41)-H41) -> #VALUE! | J41: =IF($A41="","",SUM(($A$2:$A$29="NL")*($I$2:$P$29=$B41))) -> #VALUE! | K41: =IF($A41="","",COUNTIF($I$2:$P$29,$B41)-C41) -> #VALUE! | V41: MEDIAN | W41: =MEDIAN(Y12:Y29) -> #NUM! | X41: s | Y41: stats
A42: Vincent Nordkov | B42: VN | C42: =IF($A42="","",SUM(($A$2:$A$32="Vedligeholdende")*($I$2:$P$32=$B42))) -> #VALUE! | D42: =IF($A42="","",SUM(($A$2:$A$20="NL")*($I$2:$P$20=$B42))) -> #VALUE! | E42: =IF($A42="","",SUM(($G$7:$G$20="Razorbacks")*($I$7:$P$20=$B42))+SUM(($G$7:$G$20="Tigers")*($I$7:$P$20=$B42))+SUM(($G$7:$G$20="89ers")*($I$7:$P$20=$B42))) -> #VALUE! | F42: =IF($A42="","",SUM(($G$7:$G$20="Oaks")*($I$7:$P$20=$B42))+SUM(($G$7:$G$20="Gold Diggers")*($I$7:$P$20=$B42))+SUM(($G$7:$G$20="Towers")*($I$7:$P$20=$B42))) -> #VALUE! | G42: =IF($A42="","",C42+D42) -> #VALUE! | H42: =IF($A42="","",SUM(($A$21:$A$29="NL")*($I$21:$P$29=$B42))) -> #VALUE! | I42: =IF($A42="","",COUNTIF($I$21:$P$29,$B42)-H42) -> #VALUE! | J42: =IF($A42="","",SUM(($A$2:$A$29="NL")*($I$2:$P$29=$B42))) -> #VALUE! | K42: =IF($A42="","",COUNTIF($I$2:$P$29,$B42)-C42) -> #VALUE!
...

Sheet Officials and games
N1: Games
A2: Initialer | B2: Navn | C2: Status | D2: EDK | E2: Primær | F2: Sekundær | G2: Licens | H2: Licens # | I2: Landsdel | J2: Klub | K2: Test | L2: Telefon | M2: Mail | N2: Total | O2: Primary position | P2: In primary group (not primary position) | Q2: Outside primary group
A3: AT | B3: Anders Tronier Hansen | C3: NL | E3: B | G3: NL | I3: Øst | J3: Uafhængig | M3: atronierh@gmail.com | N3: =CountIF('Plan - NL'!$I$11:$P$32,$A3) -> 1 | O3: =COUNTIFS('Plan - NL'!$M$11:$M$32,$A3) -> 1 | P3: =COUNTIFS('Plan - NL'!$N$11:$O$32,$A3) -> 0 | Q3: =COUNTIFS('Plan - NL'!$I$11:$L$32,$A3)+COUNTIFS('Plan - NL'!$P$11:$P$32,$A3) -> 0
A4: JE | B4: Jeppe Sejerø Ternander | C4: NL | D4: Ja | E4: B | F4: Anything | G4: I | H4: 6406 | I4: Øst | J4: Uafhængig | L4: 28711070 | M4: jeppe_s_holm@hotmail.com | N4: =CountIF('Plan - NL'!$I$11:$P$32,$A4) -> 4 | O4: =COUNTIFS('Plan - NL'!$N$11:$N$32,$A4) -> 0 | P4: =COUNTIFS('Plan - NL'!$M$11:$M$32,$A4) + COUNTIFS('Plan - NL'!$O$11:$O$32,$A4) -> 2 | Q4: =COUNTIFS('Plan - NL'!$I$11:$L$32,$A4)+COUNTIFS('Plan - NL'!$P$11:$P$32,$A4) -> 2
A5: BA | B5: Brian Andersen | C5: Pause (barn) | D5: Nej | E5: B | F5: Deep / Wing | G5: NL | I5: Vest | J5: Badgers | N5: =CountIF('Plan - NL'!$I$11:$P$32,$A5) -> 0 | O5: =COUNTIFS('Plan - NL'!$M$11:$M$32,$A5) -> 0 | P5: =COUNTIFS('Plan - NL'!$N$11:$O$32,$A5) -> 0 | Q5: =COUNTIFS('Plan - NL'!$I$11:$L$32,$A5)+COUNTIFS('Plan - NL'!$P$11:$P$32,$A5) -> 0
A6: OJ | B6: Claus Nordberg Larsen | C6: Ude (skade) | D6: Nej | E6: S | F6: B | G6: NL | H6: 3539 | I6: Vest | J6: Uafhængig | L6: 41817432 | M6: nordberg20@gmail.com | N6: =CountIF('Plan - NL'!$I$11:$P$32,$A6) -> 0 | O6: =COUNTIFS('Plan - NL'!$O$11:$O$32,$A6) -> 0 | P6: =COUNTIFS('Plan - NL'!$M$11:$N$32,$A6) -> 0 | Q6: =COUNTIFS('Plan - NL'!$I$11:$L$32,$A6)+COUNTIFS('Plan - NL'!$P$11:$P$32,$A6) -> 0
A7: EM | B7: Emil Riisgaard | C7: Semi | D7: Nej | E7: B | G7: C | I7: Øst | J7: Uafhængig | L7: 30481382 | M7: emilriisgaard@hotmail.com | N7: =CountIF('Plan - NL'!$I$11:$P$32,$A7) -> 0 | O7: =COUNTIFS('Plan - NL'!$M$11:$M$32,$A7) -> 0 | P7: =COUNTIFS('Plan - NL'!$N$11:$O$32,$A7) -> 0 | Q7: =COUNTIFS('Plan - NL'!$I$11:$L$32,$A7)+COUNTIFS('Plan - NL'!$P$11:$P$32,$A7) -> 0
A8: ER | B8: Erik Rasmussen | C8: NL | D8: Ja | E8: F | F8: S/B | G8: NL | H8: 711 | I8: Øst | J8: Uafhængig | L8: 40824426 | M8: erikrasmussen23@gmail.com | N8: =CountIF('Plan - NL'!$I$11:$P$32,$A8) -> 4 | O8: =COUNTIFS('Plan - NL'!$N$11:$N$32,$A8) -> 2 | P8: =COUNTIFS('Plan - NL'!$M$11:$M$32,$A8) + COUNTIFS('Plan - NL'!$O$11:$O$32,$A8) -> 2 | Q8: =COUNTIFS('Plan - NL'!$I$11:$L$32,$A8)+COUNTIFS('Plan - NL'!$P$11:$P$32,$A8) -> 0
A9: FK | B9: Frank Kristensen | C9: Ude (ELF) | D9: Ja | E9: B | G9: I | H9: 5 | I9: Øst | J9: Uafhængig | L9: 60607240 | M9: fk110871@gmail.com | N9: =CountIF('Plan - NL'!$I$11:$P$32,$A9) -> 1 | O9: =COUNTIFS('Plan - NL'!$M$11:$M$32,$A9) -> 0 | P9: =COUNTIFS('Plan - NL'!$N$11:$O$32,$A9) -> 0 | Q9: =COUNTIFS('Plan - NL'!$I$11:$L$32,$A9)+COUNTIFS('Plan - NL'!$P$11:$P$32,$A9) -> 1
A10: KL | B10: Kim Larsen | C10: NL | D10: Ja | E10: F | F10: S | G10: I | H10: 3274 | I10: Vest | J10: Uafhængig | L10: 23255155 | M10: k.m.larzen@gmail.com | N10: =CountIF('Plan - NL'!$I$11:$P$32,$A10) -> 5 | O10: =COUNTIFS('Plan - NL'!$N$11:$N$32,$A10) -> 5 | P10: =COUNTIFS('Plan - NL'!$M$11:$M$32,$A10) + COUNTIFS('Plan - NL'!$O$11:$O$32,$A10) -> 0 | Q10: =COUNTIFS('Plan - NL'!$I$11:$L$32,$A10)+COUNTIFS('Plan - NL'!$P$11:$P$32,$A10) -> 0
A11: KJ | B11: Kim Johannsen | C11: NL | D11: Ja | E11: F/S | F11: L | G11: I | H11: 2269 | I11: Øst | J11: Uafhængig | L11: 22754529 | M11: kim.johannsen@gmail.com | N11: =CountIF('Plan - NL'!$I$11:$P$32,$A11) -> 6 | O11: =COUNTIFS('Plan - NL'!$N$11:$N$32,$A11) -> 2 | P11: =COUNTIFS('Plan - NL'!$M$11:$M$32,$A11) + COUNTIFS('Plan - NL'!$O$11:$O$32,$A11) -> 4 | Q11: =COUNTIFS('Plan - NL'!$I$11:$L$32,$A11)+COUNTIFS('Plan - NL'!$P$11:$P$32,$A11) -> 0
A12: MM | B12: Martin Mikkelsen | C12: NL | D12: Nej | E12: H/L | F12: Dyb | G12: NL | H12: 628 | I12: Øst | J12: Uafhængig | L12: 26807765 | M12: mrtn.mkklsn@gmail.com | N12: =CountIF('Plan - NL'!$I$11:$P$32,$A12) -> 4 | O12: =COUNTIFS('Plan - NL'!$K$11:$K$32,$A12) -> 4 | P12: =COUNTIFS('Plan - NL'!$L$11:$L$32,$A12) -> 0 | Q12: =COUNTIFS('Plan - NL'!$I$11:$J$32,$A12)+COUNTIFS('Plan - NL'!$M$11:$P$32,$A12) -> 0
A13: JL | B13: Jesper Lytzen | C13: NL | D13: Ja | E13: L | F13: H (F/S) | G13: NL | H13: 16327 | I13: Vest | J13: Uafhængig | L13: 22614222 | M13: lytzen13@gmail.com | N13: =CountIF('Plan - NL'!$I$11:$P$32,$A13) -> 4 | O13: =COUNTIFS('Plan - NL'!$L$11:$L$32,$A13) -> 2 | P13: =COUNTIFS('Plan - NL'!$K$11:$K$32,$A13) -> 2 | Q13: =COUNTIFS('Plan - NL'!$I$11:$J$32,$A13)+COUNTIFS('Plan - NL'!$M$11:$P$32,$A13) -> 0
A14: JK | B14: Jonas Krum | C14: NL | D14: Nej | E14: L | G14: NL | H14: 3536 | I14: Øst | J14: Uafhængig | L14: 53390568 | M14: jonaskrum@gmail.com | N14: =CountIF('Plan - NL'!$I$11:$P$32,$A14) -> 1 | O14: =COUNTIFS('Plan - NL'!$L$11:$L$32,$A14) -> 0 | P14: =COUNTIFS('Plan - NL'!$K$11:$K$32,$A14) -> 0 | Q14: =COUNTIFS('Plan - NL'!$I$11:$J$32,$A14)+COUNTIFS('Plan - NL'!$M$11:$P$32,$A14) -> 1
A15: HP | B15: Hans Peter Roth | C15: NL | D15: Ja | E15: L | G15: NL
A16: MÅ | B16: Mads Åkjær | C16: Ude (ELF) | D16: Nej | E16: S | F16: R | G16: NL | H16: 10257 | I16: Øst | J16: Uafhængig | L16: 51844821 | M16: mads_aakjaer@hotmail.com | N16: =CountIF('Plan - NL'!$I$11:$P$32,$A16) -> 0 | O16: =COUNTIFS('Plan - NL'!$O$11:$O$32,$A16) -> 0 | P16: =COUNTIFS('Plan - NL'!$M$11:$N$32,$A16) -> 0 | Q16: =COUNTIFS('Plan - NL'!$I$11:$L$32,$A16)+COUNTIFS('Plan - NL'!$P$11:$P$32,$A16) -> 0
A17: NI | B17: Niels Ilberg | C17: NL | D17: Nej | E17: L/H | F17: U | G17: I | H17: 1133 | I17: Vest | J17: Uafhængig | L17: 29870710 | M17: niels@ilberg.dk | N17: =CountIF('Plan - NL'!$I$11:$P$32,$A17) -> 2 | O17: =COUNTIFS('Plan - NL'!$L$11:$L$32,$A17) -> 0 | P17: =COUNTIFS('Plan - NL'!$K$11:$K$32,$A17) -> 2 | Q17: =COUNTIFS('Plan - NL'!$I$11:$J$32,$A17)+COUNTIFS('Plan - NL'!$M$11:$P$32,$A17) -> 0
A18: FR | B18: Frank Rasmussen | C18: NL | D18: Nej | E18: R | F18: Anything | G18: I | H18: 484 | I18: Øst | J18: Uafhængig | L18: 20342617 | M18: dommer484@gmail.com | N18: =CountIF('Plan - NL'!$I$11:$P$32,$A18) -> 5 | O18: =COUNTIFS('Plan - NL'!$I$11:$I$32,$A18) -> 1 | P18: =COUNTIFS('Plan - NL'!$J$11:$J$32,$A18) -> 0 | Q18: =COUNTIFS('Plan - NL'!$K$11:$P$32,$A18) -> 4
A19: MC | B19: Mohammed Chatle | C19: Ude | D19: Nej | E19: U | F19: B | G19: NL | H19: 9074 | I19: Vest | J19: Tigers | L19: 51542401 | M19: mohammed780_2@hotmail.com | N19: =CountIF('Plan - NL'!$I$11:$P$32,$A19) -> 0 | O19: =COUNTIFS('Plan - NL'!$M$11:$M$32,$A19) -> 0 | P19: =COUNTIFS('Plan - NL'!$N$11:$O$32,$A19) -> 0 | Q19: =COUNTIFS('Plan - NL'!$I$11:$L$32,$A19)+COUNTIFS('Plan - NL'!$P$11:$P$32,$A19) -> 0
A20: MR | B20: Michael Rahbek | C20: NL | D20: Ja | E20: R | F20: S | G20: I | H20: 7255 | I20: Vest | J20: Uafhængig | L20: 60507214 | M20: michael.g.rahbek@gmail.com | N20: =CountIF('Plan - NL'!$I$11:$P$32,$A20) -> 4 | O20: =COUNTIFS('Plan - NL'!$I$11:$I$32,$A20) -> 4 | P20: =COUNTIFS('Plan - NL'!$J$11:$J$32,$A20) -> 0 | Q20: =COUNTIFS('Plan - NL'!$K$11:$P$32,$A20) -> 0
A21: SR | B21: Søren Rosenlund Pedersen | C21: Mangler | D21: Nej | E21: H | F21: L | H21: 10624 | I21: Øst | J21: Uafhængig | L21: 51501389 | M21: srosenlund88@gmail.com | N21: =CountIF('Plan - NL'!$I$11:$P$32,$A21) -> 0 | O21: =COUNTIFS('Plan - NL'!$K$11:$K$32,$A21) -> 0 | P21: =COUNTIFS('Plan - NL'!$L$11:$L$32,$A21) -> 0 | Q21: =COUNTIFS('Plan - NL'!$I$11:$J$32,$A21)+COUNTIFS('Plan - NL'!$M$11:$P$32,$A21) -> 0
A22: TM | B22: Thomas Myrup | C22: Pause | D22: Ja | E22: B | F22: F/S | G22: NL | H22: 9063 | I22: Vest | J22: Tigers | M22: eyez@eyez.dk | N22: =CountIF('Plan - NL'!$I$11:$P$32,$A22) -> 0 | O22: =COUNTIFS('Plan - NL'!$O$11:$O$32,$A22) -> 0 | P22: =COUNTIFS('Plan - NL'!$M$11:$N$32,$A22) -> 0 | Q22: =COUNTIFS('Plan - NL'!$I$11:$L$32,$A22)+COUNTIFS('Plan - NL'!$P$11:$P$32,$A22) -> 0
A23: TS | B23: Thomas Siggaard | C23: Ude (ELF) | D23: Ja | E23: H/L | F23: U | G23: I | H23: 41 | I23: Øst | J23: Uafhængig | L23: 51618450 | M23: thsiggaard@gmail.com | N23: =CountIF('Plan - NL'!$I$11:$P$32,$A23) -> 2 | O23: =COUNTIFS('Plan - NL'!$K$11:$K$32,$A23) -> 2 | P23: =COUNTIFS('Plan - NL'!$L$11:$L$32,$A23) -> 0 | Q23: =COUNTIFS('Plan - NL'!$I$11:$J$32,$A23)+COUNTIFS('Plan - NL'!$M$11:$P$32,$A23) -> 0
A24: VN | B24: Vincent Nordkov | C24: Ude (ELF) | D24: Ja | E24: U | G24: NL | I24: Øst | J24: Uafhængig | L24: 60677402 | M24: vincentnordkov@hotmail.com | N24: =CountIF('Plan - NL'!$I$11:$P$32,$A24) -> 1 | O24: =COUNTIFS('Plan - NL'!$J$11:$J$32,$A24) -> 0 | P24: =COUNTIFS('Plan - NL'!$I$11:$I$32,$A24) -> 0 | Q24: =COUNTIFS('Plan - NL'!$K$11:$P$32,$A24) -> 1
A25: AR | B25: Asbjørn Rohold | C25: NL | D25: Nej | E25: U | F25: R | G25: NL | I25: Vest | J25: Tigers | N25: =CountIF('Plan - NL'!$I$11:$P$32,$A25) -> 4 | O25: =COUNTIFS('Plan - NL'!$L$11:$L$32,$A25) -> 0 | P25: =COUNTIFS('Plan - NL'!$K$11:$K$32,$A25) -> 0 | Q25: =COUNTIFS('Plan - NL'!$I$11:$J$32,$A25)+COUNTIFS('Plan - NL'!$M$11:$P$32,$A25) -> 4
A26: TB | B26: Thomas Begonja | C26: Mangler
A27: DS | B27: Dennis Svensson | C27: NL | D27: Ja | E27: U | G27: NL
A28: TK | B28: Troels Kristensen | C28: Ude (SGD) | D28: Ja | G28: C
A29: MØ | B29: Martin Møller | C29: Mangler | E29: B
A30: MP | B30: Mark Poulsen | C30: Tilkalder | D30: Nej | E30: Wing | G30: C
A31: RH | B31: Ronnie Hansen | C31: Prospect | D31: Ja | E31: Wing | G31: C
A32: AL | B32: Alex Lind | C32: Prospect | D32: Ja | E32: Wing | G32: C
A33: TO | B33: Tommy Lønstrup Nielsen | D33: Nej | E33: Wing | G33: C
A34: AF | B34: Albert Fosberg | C34: Prospect | D34: Nej | E34: Wing
A35: BT | B35: Bo Thygesen | C35: NL | D35: Ja | G35: NL
G36: Primær | H36: Sekundær
B37: Mangler | C37: =COUNTIF($C$3:$C$35,B37) -> 3 | D37: =COUNTIF($D$3:$D$35,"Ja") -> 16 | F37: R* | G37: =COUNTIF($E$3:$E$35,$F37) -> 2 | H37: =COUNTIF($F$3:$F$35,$F37) -> 2
B38: NL | C38: =COUNTIF($C$3:$C$35,B38) -> 15 | D38: =COUNTIF($D$3:$D$35,"Nej") -> 14 | F38: U* | G38: =COUNTIF($E$3:$E$35,$F38) -> 4 | H38: =COUNTIF($F$3:$F$35,$F38) -> 2
B39: Pause* | C39: =COUNTIF($C$3:$C$35,B39) -> 2 | F39: F* | G39: =COUNTIF($E$3:$E$35,$F39) -> 3 | H39: =COUNTIF($F$3:$F$35,$F39) -> 1
B40: Inde? | C40: =COUNTIF($C$3:$C$35,B40) -> 0 | F40: S* | G40: =COUNTIF($E$3:$E$35,$F40) -> 2 | H40: =COUNTIF($F$3:$F$35,$F40) -> 3
...

Sheet Former Officials
N1: Games
A2: Initialer | B2: Navn | C2: Status | D2: EDK | E2: Primær | F2: Sekundær | G2: Licens | H2: Licens # | I2: Landsdel | J2: Klub | K2: Test | L2: Telefon | M2: Mail | N2: Total | O2: Primary position | P2: In primary group (not primary position) | Q2: Outside primary group
A3: AD | B3: Adam Durucz | C3: Former | D3: Nej | E3: L | I3: Vest | N3: =CountIF('Plan - NL'!$I$11:$P$32,$A3) -> 0 | O3: =COUNTIFS('Plan - NL'!$L$11:$L$32,$A3) -> 0 | P3: =COUNTIFS('Plan - NL'!$K$11:$K$32,$A3) -> 0 | Q3: =COUNTIFS('Plan - NL'!$I$11:$J$32,$A3)+COUNTIFS('Plan - NL'!$M$11:$P$32,$A3) -> 0
A4: CJ | B4: Christian Jørgensen | C4: Former | D4: Nej | E4: U | F4: R | G4: I | H4: 7246 | I4: Øst | J4: Uafhængig | L4: 51248482 | M4: christian@technobabble.dk | N4: =CountIF('Plan - NL'!$I$11:$P$32,$A4) -> 0 | O4: =COUNTIFS('Plan - NL'!$J$11:$J$32,$A4) -> 0 | P4: =COUNTIFS('Plan - NL'!$I$11:$I$32,$A4) -> 0 | Q4: =COUNTIFS('Plan - NL'!$K$11:$P$32,$A4) -> 0
A5: JT | B5: Jeppe Bjerg Thanning | C5: Former | D5: Nej | E5: U | G5: C | H5: 15447 | I5: Vest | J5: 89ers | N5: =CountIF('Plan - NL'!$I$11:$P$32,$A5) -> 0 | O5: =COUNTIFS('Plan - NL'!$J$11:$J$32,$A5) -> 0 | P5: =COUNTIFS('Plan - NL'!$I$11:$I$32,$A5) -> 0 | Q5: =COUNTIFS('Plan - NL'!$K$11:$P$32,$A5) -> 0
A6: KN | B6: Kim Mørch Nørgaard | C6: Former | D6: Nej | E6: H | G6: C | I6: Vest | J6: Stallions | M6: pray@live.dk | N6: =CountIF('Plan - NL'!$I$11:$P$32,$A6) -> 0 | O6: =COUNTIFS('Plan - NL'!$K$11:$K$32,$A6) -> 0 | P6: =COUNTIFS('Plan - NL'!$L$11:$L$32,$A6) -> 0 | Q6: =COUNTIFS('Plan - NL'!$I$11:$J$32,$A6)+COUNTIFS('Plan - NL'!$M$11:$P$32,$A6) -> 0
A7: SK | B7: Slava Kuzmin | C7: Former | D7: Nej | E7: B | N7: =CountIF('Plan - NL'!$I$11:$P$32,$A7) -> 0 | O7: =COUNTIFS('Plan - NL'!$M$11:$M$32,$A7) -> 0 | P7: =COUNTIFS('Plan - NL'!$N$11:$O$32,$A7) -> 0 | Q7: =COUNTIFS('Plan - NL'!$I$11:$L$32,$A7)+COUNTIFS('Plan - NL'!$P$11:$P$32,$A7) -> 0
A8: ST | B8: Søren Stiesen | C8: Former | D8: Nej | E8: L | G8: C | H8: 10548 | I8: Vest | M8: Stisen202@gmail.com | N8: =CountIF('Plan - NL'!$I$11:$P$32,$A8) -> 0 | O8: =COUNTIFS('Plan - NL'!$L$11:$L$32,$A8) -> 0 | P8: =COUNTIFS('Plan - NL'!$K$11:$K$32,$A8) -> 0 | Q8: =COUNTIFS('Plan - NL'!$I$11:$J$32,$A8)+COUNTIFS('Plan - NL'!$M$11:$P$32,$A8) -> 0
A9: UO | B9: Ulf Overbeck | C9: Former | D9: Nej | E9: U | G9: C | H9: 274 | I9: Vest | J9: Uafhængig | L9: 27205364 | M9: airulf@hotmail.com | N9: =CountIF('Plan - NL'!$I$11:$P$32,$A9) -> 0 | O9: =COUNTIFS('Plan - NL'!$J$11:$J$32,$A9) -> 0 | P9: =COUNTIFS('Plan - NL'!$I$11:$I$32,$A9) -> 0 | Q9: =COUNTIFS('Plan - NL'!$K$11:$P$32,$A9) -> 0
G10: Primær | H10: Sekundær
B11: Mangler | C11: =COUNTIF($C$3:$C$9,B11) -> 0 | D11: =COUNTIF($D$3:$D$9,"Ja") -> 0 | F11: R* | G11: =COUNTIF($E$4:$E$9,$F11) -> 0 | H11: =COUNTIF($F$4:$F$9,$F11) -> 1
B12: NL | C12: =COUNTIF($C$3:$C$9,B12) -> 0 | D12: =COUNTIF($D$3:$D$9,"Nej") -> 7 | F12: U* | G12: =COUNTIF($E$4:$E$9,$F12) -> 3 | H12: =COUNTIF($F$4:$F$9,$F12) -> 0
B13: NL (back in) | C13: =COUNTIF($C$3:$C$9,B13) -> 0 | F13: H* | G13: =COUNTIF($E$4:$E$9,$F13) -> 1 | H13: =COUNTIF($F$4:$F$9,$F13) -> 0
B14: Måske pause | C14: =COUNTIF($C$3:$C$9,B14) -> 0 | F14: L* | G14: =COUNTIF($E$4:$E$9,$F14) -> 1 | H14: =COUNTIF($F$4:$F$9,$F14) -> 0
B15: Pause* | C15: =COUNTIF($C$3:$C$9,B15) -> 0 | F15: F* | G15: =COUNTIF($E$4:$E$9,$F15) -> 0 | H15: =COUNTIF($F$4:$F$9,$F15) -> 0
B16: Inde? | C16: =COUNTIF($C$3:$C$9,B16) -> 0 | F16: S* | G16: =COUNTIF($E$4:$E$9,$F16) -> 0 | H16: =COUNTIF($F$4:$F$9,$F16) -> 0
B17: Semi | C17: =COUNTIF($C$3:$C$9,B17) -> 0 | F17: B* | G17: =COUNTIF($E$4:$E$9,$F17) -> 1 | H17: =COUNTIF($F$4:$F$9,$F17) -> 0
B18: Prospect | C18: =COUNTIF($C$3:$C$9,B18) -> 0
B19: Ude* | C19: =COUNTIF($C$3:$C$9,B19) -> 0 | F19: Tidlig plan
B20: Tilkalder | C20: =COUNTIF($C$3:$C$9,B20) -> 0 | F20: Prospects med i første runde

Sheet Plan - NL + 1. Div backup
A1: Kampnr. | B1: Runde | C1: Dag | D1: Dato | E1: Måned | F1: Tidspunkt | G1: Hjemme | H1: Ude | I1: R | J1: U | K1: H | L1: L | M1: B | N1: F | O1: S | P1: C | Q1: Note | S1: 1s | T1: 2s | U1: 3s | V1: Taske | W1: Taske IND | X1: Taske UD | Y1: Betaling | Z1: Video | AA1: Gennemseer | AC1: Game start | AD1: Game end | AE1: Video Exchanged. | AF1: Game time (easy) | AG1: Intercut time (min) | AH1: Exchange of Breakdown data | AI1: Return of break down data | AK1: Upload time | AL1: Breakdown time | AM1: Game time
B2: 2 | C2: Lørdag | D2: 15 | E2: maj | F2: 0.58333333 | G2: Badgers | H2: Hurricanes | I2: MR | J2: JT | K2: NI | L2: JL | M2: AT | N2: KL | O2: OJ | R2: Stille med 2-3 NL dommere | S2: =COUNTIF('Status data'!$A2:$H2,"1") -> 4 | T2: =COUNTIF('Status data'!$A2:$H2,"2") -> 2 | U2: =COUNTIF('Status data'!$A2:$H2,"3") -> 0 | AF2: =HOUR(AD2-AC2)&"h"&minute(AD2-AC2)&"m" -> 0h0m | AK2: =AE2-#REF! -> #REF! | AL2: =AH2-#REF! -> #REF! | AM2: =#REF!-AC2 -> #REF!
B3: 2 | C3: Lørdag | D3: 15 | E3: maj | F3: 0.58333333 | G3: Oaks | H3: Rebels | I3: CJ | J3: VN | L3: JK | M3: EM | N3: JE | O3: KJ | Q3: KEEP | R3: NL plan ud, 1. div næste uge | S3: =COUNTIF('Status data'!$A3:$H3,"1") -> 0 | T3: =COUNTIF('Status data'!$A3:$H3,"2") -> 0 | U3: =COUNTIF('Status data'!$A3:$H3,"3") -> 0 | AC3: 44059.585 | AD3: 44059.681 | AE3: 44060.033 | AF3: =HOUR(AD3-AC3)&"h"&MINUTE(AD3-AC3)&"m" -> 2h18m | AK3: =AE3-AD3 -> 0.35208333 | AL3: =AH3-AD3 -> -44059.681 | AM3: =AD3-AC3 -> 0.095833333
B4: 2 | C4: Søndag | D4: 16 | E4: maj | F4: 0.58333333 | G4: Knights | H4: Demons / Wolfpack | I4: FR | J4: CJ | K4: TS | L4: (JK) | M4: FK | N4: JE | O4: MÅ | Q4: KEEP | R4: KBH fuldt crew | S4: =COUNTIF('Status data'!$A4:$H4,"1") -> 0 | T4: =COUNTIF('Status data'!$A4:$H4,"2") -> 0 | U4: =COUNTIF('Status data'!$A4:$H4,"3") -> 0 | AF4: =HOUR(AD4-AC4)&"h"&MINUTE(AD4-AC4)&"m" -> 0h0m | AK4: =AE4-AD4 -> 0 | AL4: =AH4-AD4 -> 0 | AM4: =AD4-AC4 -> 0
B5: 3 | C5: Lørdag | D5: 22 | E5: maj | F5: 0.79166667 | G5: Towers | H5: 89ers | I5: FK | J5: CJ | K5: TS | L5: JK | M5: EM | N5: KJ | O5: MÅ | P5: FR | R5: Behold plan, til DU møde | S5: =COUNTIF('Status data'!$A5:$H5,"1") -> 0 | T5: =COUNTIF('Status data'!$A5:$H5,"2") -> 0 | U5: =COUNTIF('Status data'!$A5:$H5,"3") -> 0 | AF5: =HOUR(AD5-AC5)&"h"&MINUTE(AD5-AC5)&"m" -> 0h0m | AK5: =AH5-AD5 -> 0 | AL5: =AH5-AD5 -> 0 | AM5: =AD5-AC5 -> 0
B6: 3 | C6: Søndag | D6: 23 | E6: maj | F6: 0.58333333 | G6: Dragons | H6: Tigers | J6: AR | L6: JL | M6: (AT) | N6: KL | O6: OJ | Q6: AT over - langt? | R6: 1. Div; supervisors fx - ikke 7 | S6: =COUNTIF('Status data'!$A6:$H6,"1") -> 2 | T6: =COUNTIF('Status data'!$A6:$H6,"2") -> 1 | U6: =COUNTIF('Status data'!$A6:$H6,"3") -> 1
B7: 3 | C7: Søndag | D7: 23 | E7: maj | F7: 0.58333333 | G7: Rebels | H7: Monarchs | I7: CJ | J7: VN | L7: (JK) | M7: AT | N7: KJ | O7: MÅ | S7: =COUNTIF('Status data'!$A7:$H7,"1") -> 0 | T7: =COUNTIF('Status data'!$A7:$H7,"2") -> 0 | U7: =COUNTIF('Status data'!$A7:$H7,"3") -> 0
B8: 4 | C8: Lørdag | D8: 29 | E8: maj | F8: 0.58333333 | G8: Spartans | H8: Knights | I8: FR | J8: CJ | K8: TS | L8: JK | M8: FK | N8: KJ | O8: MÅ | P8: (EM) | Q8: KEEP, men overvej hvem der kan flyttes til d. 29. i Vejle | S8: =COUNTIF('Status data'!$A8:$H8,"1") -> 0 | T8: =COUNTIF('Status data'!$A8:$H8,"2") -> 0 | U8: =COUNTIF('Status data'!$A8:$H8,"3") -> 0
B9: 4 | C9: Lørdag | D9: 29 | E9: maj | F9: 0.79166667 | G9: Razorbacks | H9: Towers | I9: MR | J9: VN | K9: NI | L9: TB | M9: FK | N9: KL | O9: JE | P9: AT | Q9: Bil fra øst over under alle omstændigheder (B/deep/U). Hvis 8 på SNL; FK B, AT C. AT her | S9: =COUNTIF('Status data'!$A9:$H9,"1") -> 0 | T9: =COUNTIF('Status data'!$A9:$H9,"2") -> 0 | U9: =COUNTIF('Status data'!$A9:$H9,"3") -> 0
B10: 5 | C10: Lørdag | D10: 5 | E10: juni | F10: 0.58333333 | G10: Demons / Wolfpack | H10: Oaks | I10: FR | J10: CJ | K10: TS | L10: JK | M10: FK | N10: KJ | O10: MÅ | Q10: KEEP | S10: =COUNTIF('Status data'!$A10:$H10,"1") -> 0 | T10: =COUNTIF('Status data'!$A10:$H10,"2") -> 0 | U10: =COUNTIF('Status data'!$A10:$H10,"3") -> 0
B11: 5 | C11: Lørdag | D11: 5 | E11: juni | F11: 0.79166667 | G11: 89ers | H11: Gold Diggers | I11: MR | J11: JT | K11: NI | L11: JL | M11: AT | N11: KL | O11: OJ | S11: =COUNTIF('Status data'!$A11:$H11,"1") -> 0 | T11: =COUNTIF('Status data'!$A11:$H11,"2") -> 0 | U11: =COUNTIF('Status data'!$A11:$H11,"3") -> 0
B12: 6 | C12: Lørdag | D12: 12 | E12: juni | F12: 0.58333333 | G12: Knights | H12: Monarchs | I12: FR | J12: VN | K12: TS | L12: JK | M12: EM | N12: JE | O12: KJ | Q12: KEEP, men prioriterer NL kampen i Jylland | S12: =COUNTIF('Status data'!$A12:$H12,"1") -> 0 | T12: =COUNTIF('Status data'!$A12:$H12,"2") -> 0 | U12: =COUNTIF('Status data'!$A12:$H12,"3") -> 0
B13: 6 | C13: Lørdag | D13: 12 | E13: juni | F13: 0.79166667 | G13: 89ers | H13: Razorbacks | I13: MR | J13: AR | K13: NI | L13: FR/JE | M13: FK | N13: KL | O13: OJ | P13: AT | Q13: TB? JE, FR, CJ | S13: =COUNTIF('Status data'!$A13:$H13,"1") -> 0 | T13: =COUNTIF('Status data'!$A13:$H13,"2") -> 0 | U13: =COUNTIF('Status data'!$A13:$H13,"3") -> 0
B14: 7 | C14: Lørdag | D14: 19 | E14: juni | F14: 0.58333333 | G14: Gold Diggers | H14: Towers | I14: FR | J14: VN | K14: TS | L14: JK | M14: EM | N14: JE | O14: MÅ | S14: =COUNTIF('Status data'!$A14:$H14,"1") -> 0 | T14: =COUNTIF('Status data'!$A14:$H14,"2") -> 0 | U14: =COUNTIF('Status data'!$A14:$H14,"3") -> 0 | AF14: =HOUR(AD14-AC14)&"h"&minute(AD14-AC14)&"m" -> 0h0m | AK14: =AE14-AD14 -> 0 | AL14: =AH14-AD14 -> 0 | AM14: =AD14-AC14 -> 0
B15: 7 | C15: Søndag | D15: 20 | E15: juni | F15: 0.58333333 | G15: Musketeers | H15: Tigers | I15: MR | J15: AR | K15: NI | L15: (JL) | M15: (AT) | N15: (KJ) | O15: OJ | S15: =COUNTIF('Status data'!$A15:$H15,"1") -> 0 | T15: =COUNTIF('Status data'!$A15:$H15,"2") -> 0 | U15: =COUNTIF('Status data'!$A15:$H15,"3") -> 0 | AC15: 44086.585 | AD15: 44086.692 | AE15: 44087.043 | AF15: =HOUR(AD15-AC15)&"h"&MINUTE(AD15-AC15)&"m" -> 2h33m | AK15: =AE15-AD15 -> 0.35138889 | AL15: =AH15-AD15 -> -44086.692 | AM15: =AD15-AC15 -> 0.10694444
B16: 8 | C16: Lørdag | D16: 26 | E16: juni | F16: 0.58333333 | G16: Gold Diggers | H16: Razorbacks | I16: FR | J16: CJ | K16: TS | L16: JK | M16: FK | N16: KJ | O16: MÅ | S16: =COUNTIF('Status data'!$A16:$H16,"1") -> 0 | T16: =COUNTIF('Status data'!$A16:$H16,"2") -> 0 | U16: =COUNTIF('Status data'!$A16:$H16,"3") -> 0 | AF16: =HOUR(AD16-AC16)&"h"&MINUTE(AD16-AC16)&"m" -> 0h0m | AK16: =AE16-AD16 -> 0
B17: 9 | C17: Lørdag | D17: 14 | E17: august | F17: 0.58333333 | G17: Tigers | H17: Hurricanes | S17: =COUNTIF('Status data'!$A17:$H17,"1") -> 0 | T17: =COUNTIF('Status data'!$A17:$H17,"2") -> 0 | U17: =COUNTIF('Status data'!$A17:$H17,"3") -> 0
B18: 9 | C18: Lørdag | D18: 14 | E18: august | F18: 0.58333333 | G18: Gold Diggers | H18: 89ers | S18: =COUNTIF(#REF!,"1") -> #REF! | T18: =COUNTIF(#REF!,"2") -> #REF! | U18: =COUNTIF(#REF!,"3") -> #REF!
B19: 9 | C19: Søndag | D19: 15 | E19: august | F19: 0.58333333 | G19: Oaks | H19: Knights | S19: =COUNTIF('Status data'!$A18:$H18,"1") -> 0 | T19: =COUNTIF('Status data'!$A18:$H18,"2") -> 0 | U19: =COUNTIF('Status data'!$A18:$H18,"3") -> 0
B20: 10 | C20: Lørdag | D20: 21 | E20: august | F20: 0.79166667 | G20: Towers | H20: Razorbacks | S20: =COUNTIF('Status data'!$A19:$H19,"1") -> 0 | T20: =COUNTIF('Status data'!$A19:$H19,"2") -> 0 | U20: =COUNTIF('Status data'!$A19:$H19,"3") -> 0
B21: 10 | C21: Søndag | D21: 22 | E21: august | F21: 0.58333333 | G21: Badgers | H21: Musketeers | S21: =COUNTIF('Status data'!$A20:$H20,"1") -> 0 | T21: =COUNTIF('Status data'!$A20:$H20,"2") -> 0 | U21: =COUNTIF('Status data'!$A20:$H20,"3") -> 0
B22: 11 | C22: Lørdag | D22: 28 | E22: august | F22: 0.58333333 | G22: 89ers | H22: Towers | S22: =COUNTIF('Status data'!$A21:$H21,"1") -> 0 | T22: =COUNTIF('Status data'!$A21:$H21,"2") -> 0 | U22: =COUNTIF('Status data'!$A21:$H21,"3") -> 0
B23: 11 | C23: Lørdag | D23: 28 | E23: august | F23: 0.58333333 | G23: Razorbacks | H23: Gold Diggers | S23: =COUNTIF('Status data'!$A22:$H22,"1") -> 0 | T23: =COUNTIF('Status data'!$A22:$H22,"2") -> 0 | U23: =COUNTIF('Status data'!$A22:$H22,"3") -> 0
B24: 11 | C24: Søndag | D24: 29 | E24: august | F24: 0.58333333 | G24: Monarchs | H24: Demons / Wolfpack | S24: =COUNTIF('Status data'!$A23:$H23,"1") -> 0 | T24: =COUNTIF('Status data'!$A23:$H23,"2") -> 0 | U24: =COUNTIF('Status data'!$A23:$H23,"3") -> 0 | AF24: =HOUR(AD24-AC24)&"h"&minute(AD24-AC24)&"m" -> 0h0m | AK24: =AE24-AD24 -> 0
B25: 12 | C25: Lørdag | D25: 4 | E25: september | F25: 0.58333333 | G25: Dragons | H25: Rebels | S25: =COUNTIF('Status data'!$A24:$H24,"1") -> 0 | T25: =COUNTIF('Status data'!$A24:$H24,"2") -> 0 | U25: =COUNTIF('Status data'!$A24:$H24,"3") -> 0
B26: 12 | C26: Lørdag | D26: 4 | E26: september | F26: 0.79166667 | G26: Towers | H26: Gold Diggers | S26: =COUNTIF('Status data'!$A25:$H25,"1") -> 0 | T26: =COUNTIF('Status data'!$A25:$H25,"2") -> 0 | U26: =COUNTIF('Status data'!$A25:$H25,"3") -> 0
B27: 13 | C27: Lørdag | D27: 11 | E27: september | F27: 0.58333333 | G27: Demons / Wolfpack | H27: Badgers | S27: =COUNTIF('Status data'!$A26:$H26,"1") -> 0 | T27: =COUNTIF('Status data'!$A26:$H26,"2") -> 0 | U27: =COUNTIF('Status data'!$A26:$H26,"3") -> 0
B28: 13 | C28: Lørdag | D28: 11 | E28: september | F28: 0.79166667 | G28: Razorbacks | H28: 89ers | S28: =COUNTIF('Status data'!$A27:$H27,"1") -> 0 | T28: =COUNTIF('Status data'!$A27:$H27,"2") -> 0 | U28: =COUNTIF('Status data'!$A27:$H27,"3") -> 0
B29: 13 | C29: Søndag | D29: 12 | E29: september | F29: 0.58333333 | G29: Monarchs | H29: Oaks | S29: =COUNTIF('Status data'!$A28:$H28,"1") -> 0 | T29: =COUNTIF('Status data'!$A28:$H28,"2") -> 0 | U29: =COUNTIF('Status data'!$A28:$H28,"3") -> 0
A30: Semi 1 | B30: 14 | C30: Lørdag | D30: 18 | E30: september | S30: =COUNTIF('Status data'!$A29:$H29,"1") -> 0 | T30: =COUNTIF('Status data'!$A29:$H29,"2") -> 0 | U30: =COUNTIF('Status data'!$A29:$H29,"3") -> 0
A31: Semi 2 | B31: 14 | C31: Søndag | D31: 18 | E31: september | S31: =COUNTIF('Status data'!$A30:$H30,"1") -> 0 | T31: =COUNTIF('Status data'!$A30:$H30,"2") -> 0 | U31: =COUNTIF('Status data'!$A30:$H30,"3") -> 0
A32: 3rd place | B32: 15 | C32: Lørdag | D32: 2 | E32: oktober | S32: =COUNTIF('Status data'!$A31:$H31,"1") -> 0 | T32: =COUNTIF('Status data'!$A31:$H31,"2") -> 0 | U32: =COUNTIF('Status data'!$A31:$H31,"3") -> 0
A33: Mermaid Bowl | B33: 15 | C33: Lørdag | D33: 2 | E33: oktober | S33: =COUNTIF('Status data'!$A32:$H32,"1") -> 0 | T33: =COUNTIF('Status data'!$A32:$H32,"2") -> 0 | U33: =COUNTIF('Status data'!$A32:$H32,"3") -> 0
B34: 4 | C34: Lørdag/Søndag | D34: 29/30 | E34: maj | F34: 0.58333333 | G34: Hurricanes | H34: Musketeers
A36: Initialer
A37: Anders Tronier | B37: AT | C37: =COUNTIF($I$2:$O$31,B37) -> 3
A38: Brian Baagøe Andersen | B38: BA | C38: =COUNTIF($I$2:$O$31,B38) -> 0 | Q38: =DATA!I65 | W38: =SUM(Y1:Y31) -> 0 | X38: 2 | Y38: medium
A39: Bo Thygesen | B39: BT | C39: =COUNTIF($I$2:$O$31,B39) -> 0 | Q39: =DATA!I66 | V39: AVERAGE | W39: =AVERAGE(Y2:Y33) -> #DIV/0! | X39: 1 | Y39: bad
A40: Christian Jørgensen | B40: CJ | C40: =COUNTIF($I$2:$O$31,B40) -> 7 | Q40: =DATA!I67 | V40: MEDIAN | W40: =MEDIAN(Y2:Y33) -> #NUM! | X40: s | Y40: stats
A41: Emil Riisgaard | B41: EM | C41: =COUNTIF($I$2:$O$31,B41) -> 4 | V41: PROJECTED 1 | W41: =W39*40 -> #DIV/0! | X41: e | Y41: endzone
...

Sheet 2021 status
A1: Navn | B1: Initialer | C1: Yes / No | D1: Commitment | E1: Position | F1: Level
A2: Adam Durucz | B2: AD | C2: No | D2: Tilbage i Ungarn | E2: L | F2: 3
A3: Asbjørn Rohold | B3: AR | C3: Yes | D3: Ok, vil gerne lære mere | E3: U | F3: 3
A4: Anders Tronier | B4: AT | C4: Yes | D4: OK | E4: B | F4: 2
A5: Brian Andersen | B5: BA | C5: Måske | D5: Bachelor + Far | E5: B | F5: 3
A6: Christian Jørgensen | B6: CJ | C6: No | D6: Rejser til USA | E6: U | F6: 1
A7: Emil Riisgaard | B7: EM | C7: Yes | D7: Ok, så meget som muligt | E7: B | F7: 2
A8: Erik Rasmussen | B8: ER | C8: Yes | D8: Pause forår, knæ | E8: F | F8: 2
A9: Frank Kristensen | B9: FK | C9: Yes | D9: OK, så meget som muligt | E9: B | F9: 1
A10: Frank Rasmussen | B10: FR | C10: Yes | D10: OK, så meget som muligt | E10: R | F10: 1
A11: Jeppe Holm | B11: JE | C11: Yes | D11: Ok, ja til ansvar | E11: F | F11: 1
A12: Jonas Krum | B12: JK | C12: Måske | D12: OK | E12: L | F12: 1
A13: Jesper Lytzen | B13: JL | C13: Yes | D13: Ok, så meget som muligt | E13: L | F13: 2
... A25: Søren Rosenlund | B25: SR | C25: Yes | D25: Ok, men ikke meget | E25: H | F25: 1
A26: Thomas Begonja | B26: TB | C26: Yes | D26: =#N/A -> #N/A | E26: L | F26: 3
A27: Thomas Myrup | B27: TM | C27: Yes | D27: Tilbage | E27: F | F27: 3
A28: Thomas Siggaard | B28: TS | C28: Yes | D28: =#N/A -> #N/A | E28: H | F28: 1
A29: Ulf Overbeck | B29: UO | C29: No | D29: Ude | E29: U
A30: Vincent Nordkov | B30: VN | C30: Yes | D30: OK, så meget som muligt | E30: U | F30: 2
A31: Søren Skovsgaard Berthelsen | B31: SB | D31: ? | F31: 3

Sheet Status data
A1: R | B1: U | C1: H | D1: L | E1: B | F1: F | G1: S | H1: C
A2: =VLOOKUP('Plan - NL'!I11,'2021 status'!$B$2:$F$30,5,FALSE) -> 1 | B2: =VLOOKUP('Plan - NL'!J11,'2021 status'!$B$2:$F$30,5,FALSE) -> #N/A | C2: =VLOOKUP('Plan - NL'!K11,'2021 status'!$B$2:$F$30,5,FALSE) -> 1 | D2: =VLOOKUP('Plan - NL'!L11,'2021 status'!$B$2:$F$30,5,FALSE) -> 1 | E2: =VLOOKUP('Plan - NL'!M11,'2021 status'!$B$2:$F$30,5,FALSE) -> 1 | F2: =VLOOKUP('Plan - NL'!N11,'2021 status'!$B$2:$F$30,5,FALSE) -> 2 | G2: =VLOOKUP('Plan - NL'!O11,'2021 status'!$B$2:$F$30,5,FALSE) -> 2 | H2: =VLOOKUP('Plan - NL'!P11,'2021 status'!$B$2:$F$30,5,FALSE) -> #N/A
A3: =VLOOKUP(#REF!,'2021 status'!$B$2:$F$30,5,FALSE) -> #REF! | B3: =VLOOKUP(#REF!,'2021 status'!$B$2:$F$30,5,FALSE) -> #REF! | C3: =VLOOKUP(#REF!,'2021 status'!$B$2:$F$30,5,FALSE) -> #REF! | D3: =VLOOKUP(#REF!,'2021 status'!$B$2:$F$30,5,FALSE) -> #REF! | E3: =VLOOKUP(#REF!,'2021 status'!$B$2:$F$30,5,FALSE) -> #REF! | F3: =VLOOKUP(#REF!,'2021 status'!$B$2:$F$30,5,FALSE) -> #REF! | G3: =VLOOKUP(#REF!,'2021 status'!$B$2:$F$30,5,FALSE) -> #REF! | H3: =VLOOKUP(#REF!,'2021 status'!$B$2:$F$30,5,FALSE) -> #REF!
A4: =VLOOKUP(#REF!,'2021 status'!$B$2:$F$30,5,FALSE) -> #REF! | B4: =VLOOKUP(#REF!,'2021 status'!$B$2:$F$30,5,FALSE) -> #REF! | C4: =VLOOKUP(#REF!,'2021 status'!$B$2:$F$30,5,FALSE) -> #REF! | D4: =VLOOKUP(#REF!,'2021 status'!$B$2:$F$30,5,FALSE) -> #REF! | E4: =VLOOKUP(#REF!,'2021 status'!$B$2:$F$30,5,FALSE) -> #REF! | F4: =VLOOKUP(#REF!,'2021 status'!$B$2:$F$30,5,FALSE) -> #REF! | G4: =VLOOKUP(#REF!,'2021 status'!$B$2:$F$30,5,FALSE) -> #REF! | H4: =VLOOKUP(#REF!,'2021 status'!$B$2:$F$30,5,FALSE) -> #REF!
A5: =VLOOKUP(#REF!,'2021 status'!$B$2:$F$30,5,FALSE) -> #REF! | B5: =VLOOKUP(#REF!,'2021 status'!$B$2:$F$30,5,FALSE) -> #REF! | C5: =VLOOKUP(#REF!,'2021 status'!$B$2:$F$30,5,FALSE) -> #REF! | D5: =VLOOKUP(#REF!,'2021 status'!$B$2:$F$30,5,FALSE) -> #REF! | E5: =VLOOKUP(#REF!,'2021 status'!$B$2:$F$30,5,FALSE) -> #REF! | F5: =VLOOKUP(#REF!,'2021 status'!$B$2:$F$30,5,FALSE) -> #REF! | G5: =VLOOKUP(#REF!,'2021 status'!$B$2:$F$30,5,FALSE) -> #REF! | H5: =VLOOKUP(#REF!,'2021 status'!$B$2:$F$30,5,FALSE) -> #REF!
A6: =VLOOKUP('Plan - NL'!I12,'2021 status'!$B$2:$F$30,5,FALSE) -> 1 | B6: =VLOOKUP('Plan - NL'!J12,'2021 status'!$B$2:$F$30,5,FALSE) -> 3 | C6: =VLOOKUP('Plan - NL'!K12,'2021 status'!$B$2:$F$30,5,FALSE) -> 2 | D6: =VLOOKUP('Plan - NL'!L12,'2021 status'!$B$2:$F$30,5,FALSE) -> #N/A | E6: =VLOOKUP('Plan - NL'!M12,'2021 status'!$B$2:$F$30,5,FALSE) -> #N/A | F6: =VLOOKUP('Plan - NL'!N12,'2021 status'!$B$2:$F$30,5,FALSE) -> 1 | G6: =VLOOKUP('Plan - NL'!O12,'2021 status'!$B$2:$F$30,5,FALSE) -> #N/A | H6: =VLOOKUP('Plan - NL'!P12,'2021 status'!$B$2:$F$30,5,FALSE) -> #N/A
A7: =VLOOKUP(#REF!,'2021 status'!$B$2:$F$30,5,FALSE) -> #REF! | B7: =VLOOKUP(#REF!,'2021 status'!$B$2:$F$30,5,FALSE) -> #REF! | C7: =VLOOKUP(#REF!,'2021 status'!$B$2:$F$30,5,FALSE) -> #REF! | D7: =VLOOKUP(#REF!,'2021 status'!$B$2:$F$30,5,FALSE) -> #REF! | E7: =VLOOKUP(#REF!,'2021 status'!$B$2:$F$30,5,FALSE) -> #REF! | F7: =VLOOKUP(#REF!,'2021 status'!$B$2:$F$30,5,FALSE) -> #REF! | G7: =VLOOKUP(#REF!,'2021 status'!$B$2:$F$30,5,FALSE) -> #REF! | H7: =VLOOKUP(#REF!,'2021 status'!$B$2:$F$30,5,FALSE) -> #REF!
A8: =VLOOKUP(#REF!,'2021 status'!$B$2:$F$30,5,FALSE) -> #REF! | B8: =VLOOKUP(#REF!,'2021 status'!$B$2:$F$30,5,FALSE) -> #REF! | C8: =VLOOKUP(#REF!,'2021 status'!$B$2:$F$30,5,FALSE) -> #REF! | D8: =VLOOKUP(#REF!,'2021 status'!$B$2:$F$30,5,FALSE) -> #REF! | E8: =VLOOKUP(#REF!,'2021 status'!$B$2:$F$30,5,FALSE) -> #REF! | F8: =VLOOKUP(#REF!,'2021 status'!$B$2:$F$30,5,FALSE) -> #REF! | G8: =VLOOKUP(#REF!,'2021 status'!$B$2:$F$30,5,FALSE) -> #REF! | H8: =VLOOKUP(#REF!,'2021 status'!$B$2:$F$30,5,FALSE) -> #REF!
A9: =VLOOKUP(#REF!,'2021 status'!$B$2:$F$30,5,FALSE) -> #REF! | B9: =VLOOKUP(#REF!,'2021 status'!$B$2:$F$30,5,FALSE) -> #REF! | C9: =VLOOKUP(#REF!,'2021 status'!$B$2:$F$30,5,FALSE) -> #REF! | D9: =VLOOKUP(#REF!,'2021 status'!$B$2:$F$30,5,FALSE) -> #REF! | E9: =VLOOKUP(#REF!,'2021 status'!$B$2:$F$30,5,FALSE) -> #REF! | F9: =VLOOKUP(#REF!,'2021 status'!$B$2:$F$30,5,FALSE) -> #REF! | G9: =VLOOKUP(#REF!,'2021 status'!$B$2:$F$30,5,FALSE) -> #REF! | H9: =VLOOKUP(#REF!,'2021 status'!$B$2:$F$30,5,FALSE) -> #REF!
A10: =VLOOKUP(#REF!,'2021 status'!$B$2:$F$30,5,FALSE) -> #REF! | B10: =VLOOKUP(#REF!,'2021 status'!$B$2:$F$30,5,FALSE) -> #REF! | C10: =VLOOKUP(#REF!,'2021 status'!$B$2:$F$30,5,FALSE) -> #REF! | D10: =VLOOKUP(#REF!,'2021 status'!$B$2:$F$30,5,FALSE) -> #REF! | E10: =VLOOKUP(#REF!,'2021 status'!$B$2:$F$30,5,FALSE) -> #REF! | F10: =VLOOKUP(#REF!,'2021 status'!$B$2:$F$30,5,FALSE) -> #REF! | G10: =VLOOKUP(#REF!,'2021 status'!$B$2:$F$30,5,FALSE) -> #REF! | H10: =VLOOKUP(#REF!,'2021 status'!$B$2:$F$30,5,FALSE) -> #REF!
A11: =VLOOKUP(#REF!,'2021 status'!$B$2:$F$30,5,FALSE) -> #REF! | B11: =VLOOKUP(#REF!,'2021 status'!$B$2:$F$30,5,FALSE) -> #REF! | C11: =VLOOKUP(#REF!,'2021 status'!$B$2:$F$30,5,FALSE) -> #REF! | D11: =VLOOKUP(#REF!,'2021 status'!$B$2:$F$30,5,FALSE) -> #REF! | E11: =VLOOKUP(#REF!,'2021 status'!$B$2:$F$30,5,FALSE) -> #REF! | F11: =VLOOKUP(#REF!,'2021 status'!$B$2:$F$30,5,FALSE) -> #REF! | G11: =VLOOKUP(#REF!,'2021 status'!$B$2:$F$30,5,FALSE) -> #REF! | H11: =VLOOKUP(#REF!,'2021 status'!$B$2:$F$30,5,FALSE) -> #REF!
A12: =VLOOKUP('Plan - NL'!I24,'2021 status'!$B$2:$F$30,5,FALSE) -> #N/A | B12: =VLOOKUP('Plan - NL'!J24,'2021 status'!$B$2:$F$30,5,FALSE) -> #N/A | C12: =VLOOKUP('Plan - NL'!K24,'2021 status'!$B$2:$F$30,5,FALSE) -> #N/A | D12: =VLOOKUP('Plan - NL'!L24,'2021 status'!$B$2:$F$30,5,FALSE) -> #N/A | E12: =VLOOKUP('Plan - NL'!M24,'2021 status'!$B$2:$F$30,5,FALSE) -> #N/A | F12: =VLOOKUP('Plan - NL'!N24,'2021 status'!$B$2:$F$30,5,FALSE) -> #N/A | G12: =VLOOKUP('Plan - NL'!O24,'2021 status'!$B$2:$F$30,5,FALSE) -> #N/A | H12: =VLOOKUP('Plan - NL'!P24,'2021 status'!$B$2:$F$30,5,FALSE) -> #N/A
A13: =VLOOKUP(#REF!,'2021 status'!$B$2:$F$30,5,FALSE) -> #REF! | B13: =VLOOKUP(#REF!,'2021 status'!$B$2:$F$30,5,FALSE) -> #REF! | C13: =VLOOKUP(#REF!,'2021 status'!$B$2:$F$30,5,FALSE) -> #REF! | D13: =VLOOKUP(#REF!,'2021 status'!$B$2:$F$30,5,FALSE) -> #REF! | E13: =VLOOKUP(#REF!,'2021 status'!$B$2:$F$30,5,FALSE) -> #REF! | F13: =VLOOKUP(#REF!,'2021 status'!$B$2:$F$30,5,FALSE) -> #REF! | G13: =VLOOKUP(#REF!,'2021 status'!$B$2:$F$30,5,FALSE) -> #REF! | H13: =VLOOKUP(#REF!,'2021 status'!$B$2:$F$30,5,FALSE) -> #REF!
A14: =VLOOKUP(#REF!,'2021 status'!$B$2:$F$30,5,FALSE) -> #REF! | B14: =VLOOKUP(#REF!,'2021 status'!$B$2:$F$30,5,FALSE) -> #REF! | C14: =VLOOKUP(#REF!,'2021 status'!$B$2:$F$30,5,FALSE) -> #REF! | D14: =VLOOKUP(#REF!,'2021 status'!$B$2:$F$30,5,FALSE) -> #REF! | E14: =VLOOKUP(#REF!,'2021 status'!$B$2:$F$30,5,FALSE) -> #REF! | F14: =VLOOKUP(#REF!,'2021 status'!$B$2:$F$30,5,FALSE) -> #REF! | G14: =VLOOKUP(#REF!,'2021 status'!$B$2:$F$30,5,FALSE) -> #REF! | H14: =VLOOKUP(#REF!,'2021 status'!$B$2:$F$30,5,FALSE) -> #REF!
A15: =VLOOKUP(#REF!,'2021 status'!$B$2:$F$30,5,FALSE) -> #REF! | B15: =VLOOKUP(#REF!,'2021 status'!$B$2:$F$30,5,FALSE) -> #REF! | C15: =VLOOKUP(#REF!,'2021 status'!$B$2:$F$30,5,FALSE) -> #REF! | D15: =VLOOKUP(#REF!,'2021 status'!$B$2:$F$30,5,FALSE) -> #REF! | E15: =VLOOKUP(#REF!,'2021 status'!$B$2:$F$30,5,FALSE) -> #REF! | F15: =VLOOKUP(#REF!,'2021 status'!$B$2:$F$30,5,FALSE) -> #REF! | G15: =VLOOKUP(#REF!,'2021 status'!$B$2:$F$30,5,FALSE) -> #REF! | H15: =VLOOKUP(#REF!,'2021 status'!$B$2:$F$30,5,FALSE) -> #REF!
A16: =VLOOKUP(#REF!,'2021 status'!$B$2:$F$30,5,FALSE) -> #REF! | B16: =VLOOKUP(#REF!,'2021 status'!$B$2:$F$30,5,FALSE) -> #REF! | C16: =VLOOKUP(#REF!,'2021 status'!$B$2:$F$30,5,FALSE) -> #REF! | D16: =VLOOKUP(#REF!,'2021 status'!$B$2:$F$30,5,FALSE) -> #REF! | E16: =VLOOKUP(#REF!,'2021 status'!$B$2:$F$30,5,FALSE) -> #REF! | F16: =VLOOKUP(#REF!,'2021 status'!$B$2:$F$30,5,FALSE) -> #REF! | G16: =VLOOKUP(#REF!,'2021 status'!$B$2:$F$30,5,FALSE) -> #REF! | H16: =VLOOKUP(#REF!,'2021 status'!$B$2:$F$30,5,FALSE) -> #REF!
A17: =VLOOKUP(#REF!,'2021 status'!$B$2:$F$30,5,FALSE) -> #REF! | B17: =VLOOKUP(#REF!,'2021 status'!$B$2:$F$30,5,FALSE) -> #REF! | C17: =VLOOKUP(#REF!,'2021 status'!$B$2:$F$30,5,FALSE) -> #REF! | D17: =VLOOKUP(#REF!,'2021 status'!$B$2:$F$30,5,FALSE) -> #REF! | E17: =VLOOKUP(#REF!,'2021 status'!$B$2:$F$30,5,FALSE) -> #REF! | F17: =VLOOKUP(#REF!,'2021 status'!$B$2:$F$30,5,FALSE) -> #REF! | G17: =VLOOKUP(#REF!,'2021 status'!$B$2:$F$30,5,FALSE) -> #REF! | H17: =VLOOKUP(#REF!,'2021 status'!$B$2:$F$30,5,FALSE) -> #REF!
A18: =VLOOKUP(#REF!,'2021 status'!$B$2:$F$30,5,FALSE) -> #REF! | B18: =VLOOKUP(#REF!,'2021 status'!$B$2:$F$30,5,FALSE) -> #REF! | C18: =VLOOKUP(#REF!,'2021 status'!$B$2:$F$30,5,FALSE) -> #REF! | D18: =VLOOKUP(#REF!,'2021 status'!$B$2:$F$30,5,FALSE) -> #REF! | E18: =VLOOKUP(#REF!,'2021 status'!$B$2:$F$30,5,FALSE) -> #REF! | F18: =VLOOKUP(#REF!,'2021 status'!$B$2:$F$30,5,FALSE) -> #REF! | G18: =VLOOKUP(#REF!,'2021 status'!$B$2:$F$30,5,FALSE) -> #REF! | H18: =VLOOKUP(#REF!,'2021 status'!$B$2:$F$30,5,FALSE) -> #REF!
A19: =VLOOKUP('Plan - NL'!I28,'2021 status'!$B$2:$F$30,5,FALSE) -> #N/A | B19: =VLOOKUP('Plan - NL'!J28,'2021 status'!$B$2:$F$30,5,FALSE) -> #N/A | C19: =VLOOKUP('Plan - NL'!K28,'2021 status'!$B$2:$F$30,5,FALSE) -> #N/A | D19: =VLOOKUP('Plan - NL'!L28,'2021 status'!$B$2:$F$30,5,FALSE) -> #N/A | E19: =VLOOKUP('Plan - NL'!M28,'2021 status'!$B$2:$F$30,5,FALSE) -> #N/A | F19: =VLOOKUP('Plan - NL'!N28,'2021 status'!$B$2:$F$30,5,FALSE) -> #N/A | G19: =VLOOKUP('Plan - NL'!O28,'2021 status'!$B$2:$F$30,5,FALSE) -> #N/A | H19: =VLOOKUP('Plan - NL'!P28,'2021 status'!$B$2:$F$30,5,FALSE) -> #N/A
A20: =VLOOKUP(#REF!,'2021 status'!$B$2:$F$30,5,FALSE) -> #REF! | B20: =VLOOKUP(#REF!,'2021 status'!$B$2:$F$30,5,FALSE) -> #REF! | C20: =VLOOKUP(#REF!,'2021 status'!$B$2:$F$30,5,FALSE) -> #REF! | D20: =VLOOKUP(#REF!,'2021 status'!$B$2:$F$30,5,FALSE) -> #REF! | E20: =VLOOKUP(#REF!,'2021 status'!$B$2:$F$30,5,FALSE) -> #REF! | F20: =VLOOKUP(#REF!,'2021 status'!$B$2:$F$30,5,FALSE) -> #REF! | G20: =VLOOKUP(#REF!,'2021 status'!$B$2:$F$30,5,FALSE) -> #REF! | H20: =VLOOKUP(#REF!,'2021 status'!$B$2:$F$30,5,FALSE) -> #REF!
A21: =VLOOKUP(#REF!,'2021 status'!$B$2:$F$30,5,FALSE) -> #REF! | B21: =VLOOKUP(#REF!,'2021 status'!$B$2:$F$30,5,FALSE) -> #REF! | C21: =VLOOKUP(#REF!,'2021 status'!$B$2:$F$30,5,FALSE) -> #REF! | D21: =VLOOKUP(#REF!,'2021 status'!$B$2:$F$30,5,FALSE) -> #REF! | E21: =VLOOKUP(#REF!,'2021 status'!$B$2:$F$30,5,FALSE) -> #REF! | F21: =VLOOKUP(#REF!,'2021 status'!$B$2:$F$30,5,FALSE) -> #REF! | G21: =VLOOKUP(#REF!,'2021 status'!$B$2:$F$30,5,FALSE) -> #REF! | H21: =VLOOKUP(#REF!,'2021 status'!$B$2:$F$30,5,FALSE) -> #REF!
A22: =VLOOKUP(#REF!,'2021 status'!$B$2:$F$30,5,FALSE) -> #REF! | B22: =VLOOKUP(#REF!,'2021 status'!$B$2:$F$30,5,FALSE) -> #REF! | C22: =VLOOKUP(#REF!,'2021 status'!$B$2:$F$30,5,FALSE) -> #REF! | D22: =VLOOKUP(#REF!,'2021 status'!$B$2:$F$30,5,FALSE) -> #REF! | E22: =VLOOKUP(#REF!,'2021 status'!$B$2:$F$30,5,FALSE) -> #REF! | F22: =VLOOKUP(#REF!,'2021 status'!$B$2:$F$30,5,FALSE) -> #REF! | G22: =VLOOKUP(#REF!,'2021 status'!$B$2:$F$30,5,FALSE) -> #REF! | H22: =VLOOKUP(#REF!,'2021 status'!$B$2:$F$30,5,FALSE) -> #REF!

Sheet 2020 status
A1: Initials | B1: Yes / No | C1: Commitment | D1: Position | E1: Level
A2: AD | B2: Yes | D2: L | E2: 3
A3: AR | B3: Yes | D3: S | E3: 3
A4: AT | B4: Yes | D4: B | E4: 2
A5: BA | B5: Yes | D5: B | E5: 3
A6: CJ | B6: Yes | C6: Som 2019 | D6: U | E6: 1
A7: EM | B7: Yes | C7: Orlov studie | D7: B | E7: 2
A8: ER | B8: Yes | C8: Virker mere klar end tidligere | D8: F | E8: 2
A9: FK | B9: Yes | D9: B | E9: 1
A10: FR | B10: Yes | D10: R | E10: 1
A11: JE | B11: Yes | D11: F | E11: 1
A12: JK | B12: Yes | D12: L | E12: 1
A13: JL | B13: Yes | D13: L | E13: 2
A14: JT | B14: Pause | C14: Far marts | D14: U
A15: KJ | B15: Yes | D15: F | E15: 2
A16: KL | B16: Yes | D16: F | E16: 1
A17: KN | B17: Yes | D17: H | E17: 3
A18: MC | B18: Yes | D18: B | E18: 3
A19: MM | B19: Yes | D19: L | E19: 1
A20: MR | B20: Yes | D20: R | E20: 1
A21: MÅ | B21: Yes | D21: S | E21: 2
A22: NI | B22: Yes | D22: L | E22: 1
A23: OJ | B23: Yes | D23: S | E23: 2
A24: SK | B24: Yes | C24: Might only be available until May | D24: B | E24: 2
A25: SR | B25: Yes | D25: H | E25: 1
A26: TB | B26: Yes | D26: L | E26: 3
A27: TM | B27: Yes | D27: F | E27: 3
A28: TS | B28: Yes | D28: H | E28: 1
A29: UO | B29: No | D29: U
A30: VN | B30: Yes | D30: U | E30: 2

Sheet Tasks
A1: NL tasks
B2: 1. person | C2: 2. person
A3: Kamppapirer | B3: KL
A4: Kamptasker | B4: JK | C4: KJ
A5: Radioer | B5: KK | C5: SR
A6: Assignmemt | B6: MM | C6: KL / JE
A7: Gennemseening af kampe | B7: SR | C7: KL
A8: Deeps | B8: FK
A9: Wings | B9: MM
A10: Ref / Ump | B10: MM
A11: Kontakt til DAFF | B11: MM

Sheet Stats
H1: Dommerudgifter | I1: Gennemsnit | K1: Upload tid | L1: Gennemsnit | M1: MXl | N1: Grænse | O1: Sluttidspunkt | P1: Varighed | Q1: Varighed af kamp | R1: MXl for varighed
A2: =#REF! -> #REF! | B2: =#REF! -> #REF! | C2: =#REF! -> #REF! | D2: =#REF! -> #REF! | E2: =#REF! -> #REF! | F2: =#REF! -> #REF! | G2: =C2&" "&B2 -> #REF! | H2: =#REF! -> #REF! | I2: =AVERAGE(H$2:H$51) -> #REF! | J2: =#REF! -> #REF! | K2: =IF(DAY(J2)>30,24+HOUR(J2)+MINUTE(J2)/60,HOUR(J2)+MINUTE(J2)/60) -> #REF! | L2: =AVERAGE(K$2:K$51) -> #REF! | M2: 24 | N2: 36 | O2: =#REF! -> #REF! | P2: =IF(O2>0,O2-E2,"") -> #REF! | Q2: =HOUR(P2)+MINUTE(P2)/60 -> #REF! | R2: =HOUR("02.23.00")+MINUTE("02.23.00")/60 -> #VALUE! | S2: =AVERAGE(Q2:Q61) -> #REF! | T2: =O2-E2 -> #REF! | U2: =IF(DAY(T2)>30,24+HOUR(T2)+MINUTE(T2)/60,HOUR(T2)+MINUTE(T2)/60) -> #REF!
A3: =#REF! -> #REF! | B3: =#REF! -> #REF! | C3: =#REF! -> #REF! | D3: =#REF! -> #REF! | E3: =#REF! -> #REF! | F3: =#REF! -> #REF! | G3: =C3&" "&B3 -> #REF! | H3: =#REF! -> #REF! | I3: =AVERAGE(H$2:H$51) -> #REF! | J3: =#REF! -> #REF! | K3: =IF(DAY(J3)>30,24+HOUR(J3)+MINUTE(J3)/60,HOUR(J3)+MINUTE(J3)/60) -> #REF! | L3: =AVERAGE(K$2:K$51) -> #REF! | M3: 24 | N3: 36 | O3: =#REF! -> #REF! | P3: =IF(O3>0,O3-E3,"") -> #REF! | Q3: =HOUR(P3)+MINUTE(P3)/60 -> #REF! | R3: =HOUR("02.23.00")+MINUTE("02.23.00")/60 -> #VALUE! | T3: =O3-E3 -> #REF! | U3: =IF(DAY(T3)>30,24+HOUR(T3)+MINUTE(T3)/60,HOUR(T3)+MINUTE(T3)/60) -> #REF!
A4: =#REF! -> #REF! | B4: =#REF! -> #REF! | C4: =#REF! -> #REF! | D4: =#REF! -> #REF! | E4: =#REF! -> #REF! | F4: =#REF! -> #REF! | G4: =C4&" "&B4 -> #REF! | H4: =#REF! -> #REF! | I4: =AVERAGE(H$2:H$51) -> #REF! | J4: =#REF! -> #REF! | K4: =IF(DAY(J4)>30,24+HOUR(J4)+MINUTE(J4)/60,HOUR(J4)+MINUTE(J4)/60) -> #REF! | L4: =AVERAGE(K$2:K$51) -> #REF! | M4: 24 | N4: 36 | O4: =#REF! -> #REF! | P4: =IF(O4>0,O4-E4,"") -> #REF! | Q4: =HOUR(P4)+MINUTE(P4)/60 -> #REF! | R4: =HOUR("02.23.00")+MINUTE("02.23.00")/60 -> #VALUE! | T4: =O4-E4 -> #REF! | U4: =IF(DAY(T4)>30,24+HOUR(T4)+MINUTE(T4)/60,HOUR(T4)+MINUTE(T4)/60) -> #REF!
A5: =#REF! -> #REF! | B5: =#REF! -> #REF! | C5: =#REF! -> #REF! | D5: =#REF! -> #REF! | E5: =#REF! -> #REF! | F5: =#REF! -> #REF! | G5: =C5&" "&B5 -> #REF! | H5: =#REF! -> #REF! | I5: =AVERAGE(H$2:H$51) -> #REF! | J5: =#REF! -> #REF! | K5: =IF(DAY(J5)>30,24+HOUR(J5)+MINUTE(J5)/60,HOUR(J5)+MINUTE(J5)/60) -> #REF! | L5: =AVERAGE(K$2:K$51) -> #REF! | M5: 24 | N5: 36 | O5: =#REF! -> #REF! | P5: =IF(O5>0,O5-E5,"") -> #REF! | Q5: =HOUR(P5)+MINUTE(P5)/60 -> #REF! | R5: =HOUR("02.23.00")+MINUTE("02.23.00")/60 -> #VALUE! | T5: =O5-E5 -> #REF! | U5: =IF(DAY(T5)>30,24+HOUR(T5)+MINUTE(T5)/60,HOUR(T5)+MINUTE(T5)/60) -> #REF!
A6: =#REF! -> #REF! | B6: =#REF! -> #REF! | C6: =#REF! -> #REF! | D6: =#REF! -> #REF! | E6: =#REF! -> #REF! | F6: =#REF! -> #REF! | G6: =C6&" "&B6 -> #REF! | H6: =#REF! -> #REF! | I6: =AVERAGE(H$2:H$51) -> #REF! | J6: =#REF! -> #REF! | K6: =IF(DAY(J6)>30,24+HOUR(J6)+MINUTE(J6)/60,HOUR(J6)+MINUTE(J6)/60) -> #REF! | L6: =AVERAGE(K$2:K$51) -> #REF! | M6: 24 | N6: 36 | O6: =#REF! -> #REF! | P6: =IF(O6>0,O6-E6,"") -> #REF! | Q6: =HOUR(P6)+MINUTE(P6)/60 -> #REF! | R6: =HOUR("02.23.00")+MINUTE("02.23.00")/60 -> #VALUE! | T6: =O6-E6 -> #REF! | U6: =IF(DAY(T6)>30,24+HOUR(T6)+MINUTE(T6)/60,HOUR(T6)+MINUTE(T6)/60) -> #REF!
A7: =#REF! -> #REF! | B7: =#REF! -> #REF! | C7: =#REF! -> #REF! | D7: =#REF! -> #REF! | E7: =#REF! -> #REF! | F7: =#REF! -> #REF! | G7: =C7&" "&B7 -> #REF! | H7: =#REF! -> #REF! | I7: =AVERAGE(H$2:H$51) -> #REF! | J7: =#REF! -> #REF! | K7: =IF(DAY(J7)>30,24+HOUR(J7)+MINUTE(J7)/60,HOUR(J7)+MINUTE(J7)/60) -> #REF! | L7: =AVERAGE(K$2:K$51) -> #REF! | M7: 24 | N7: 36 | O7: =#REF! -> #REF! | P7: =IF(O7>0,O7-E7,"") -> #REF! | Q7: =HOUR(P7)+MINUTE(P7)/60 -> #REF! | R7: =HOUR("02.23.00")+MINUTE("02.23.00")/60 -> #VALUE! | T7: =O7-E7 -> #REF! | U7: =IF(DAY(T7)>30,24+HOUR(T7)+MINUTE(T7)/60,HOUR(T7)+MINUTE(T7)/60) -> #REF!
A8: =#REF! -> #REF! | B8: =#REF! -> #REF! | C8: =#REF! -> #REF! | D8: =#REF! -> #REF! | E8: =#REF! -> #REF! | F8: =#REF! -> #REF! | G8: =C8&" "&B8 -> #REF! | H8: =#REF! -> #REF! | I8: =AVERAGE(H$2:H$51) -> #REF! | J8: =#REF! -> #REF! | K8: =IF(DAY(J8)>30,24+HOUR(J8)+MINUTE(J8)/60,HOUR(J8)+MINUTE(J8)/60) -> #REF! | L8: =AVERAGE(K$2:K$51) -> #REF! | M8: 24 | N8: 36 | O8: =#REF! -> #REF! | P8: =IF(O8>0,O8-E8,"") -> #REF! | Q8: =HOUR(P8)+MINUTE(P8)/60 -> #REF! | R8: =HOUR("02.23.00")+MINUTE("02.23.00")/60 -> #VALUE! | T8: =O8-E8 -> #REF! | U8: =IF(DAY(T8)>30,24+HOUR(T8)+MINUTE(T8)/60,HOUR(T8)+MINUTE(T8)/60) -> #REF!
A9: =#REF! -> #REF! | B9: =#REF! -> #REF! | C9: =#REF! -> #REF! | D9: =#REF! -> #REF! | E9: =#REF! -> #REF! | F9: =#REF! -> #REF! | G9: =C9&" "&B9 -> #REF! | H9: =#REF! -> #REF! | I9: =AVERAGE(H$2:H$51) -> #REF! | J9: =#REF! -> #REF! | K9: =IF(DAY(J9)>30,24+HOUR(J9)+MINUTE(J9)/60,HOUR(J9)+MINUTE(J9)/60) -> #REF! | L9: =AVERAGE(K$2:K$51) -> #REF! | M9: 24 | N9: 36 | O9: =#REF! -> #REF! | P9: =IF(O9>0,O9-E9,"") -> #REF! | Q9: =HOUR(P9)+MINUTE(P9)/60 -> #REF! | R9: =HOUR("02.23.00")+MINUTE("02.23.00")/60 -> #VALUE! | T9: =O9-E9 -> #REF! | U9: =IF(DAY(T9)>30,24+HOUR(T9)+MINUTE(T9)/60,HOUR(T9)+MINUTE(T9)/60) -> #REF!
